Workbook

Sheet Summary (UNCLASS)
B1: RLT-3 | E1: RLT-7 | H1: RLT-4 | K1: 12TH MAR | N1: HQBN | Q1: 3d LAR | T1: 3d RECON | W1: 3d LE Bn | Z1: AATF TACON V31 | AC1: 1ST CEB H&S CO ENG SPT CO | AF1: 3D MARDIV TOTAL
A2: PAX | B2: ='RLT3 (UNCLASS)'!E7 -> 0 | E2: ='RLT7(UNCLASS)'!E7 -> 0 | H2: ='RLT4(UNCLASS)'!E7 -> 0 | K2: ='12TH REG(UNCLASS)'!E7 -> 0 | N2: ='HQBN(UNCLASS)'!E7 -> 0 | Q2: ='LAR(UNCLASS)'!E7 -> 0 | T2: ='RECON(UNCLASS)'!E7 -> 0 | W2: ='LE(UNCLASS)'!E7 -> 0 | Z2: ='AATF(UNCLASS)'!E7 -> 0 | AC2: ='CEB(UNCLASS)'!E7 -> 0 | AF2: =SUM(B2,E2,H2,K2,N2,Q2,T2,W2,Z2,AC2) -> 0 | AI2: PAX
A3: CLASS I CHOW ASLT RATE (3 M/M/D) | B3: 1 DOS | C3: 3 DOS | E3: 1 DOS | F3: 3 DOS | H3: 1 DOS | I3: 3 DOS | K3: 1 DOS | L3: 3 DOS | N3: 1 DOS | O3: 3 DOS | Q3: 1 DOS | R3: 3 DOS | T3: 1 DOS | U3: 3 DOS | W3: 1 DOS | X3: 3 DOS | Z3: 1 DOS | AA3: 3 DOS | AC3: 1 DOS | AD3: 3 DOS | AF3: 1 DOS | AG3: 3 DOS | AI3: CLASS I CHOW ASLT RATE (3 M/M/D)
A4: PALLETS | B4: ='RLT3 (UNCLASS)'!F23 -> 0 | C4: =B4*3 -> 0 | E4: ='RLT7(UNCLASS)'!F23 -> 0 | F4: =E4*3 -> 0 | H4: ='RLT4(UNCLASS)'!F23 -> 0 | I4: =H4*3 -> 0 | K4: ='12TH REG(UNCLASS)'!F23 -> 0 | L4: =K4*3 -> 0 | N4: ='HQBN(UNCLASS)'!F23 -> 0 | O4: =N4*3 -> 0 | Q4: ='LAR(UNCLASS)'!F23 -> 0 | R4: =Q4*3 -> 0 | T4: ='RECON(UNCLASS)'!F23 -> 0 | U4: =T4*3 -> 0 | W4: ='LE(UNCLASS)'!F23 -> 0 | X4: =W4*3 -> 0 | Z4: ='AATF(UNCLASS)'!F23 -> 0 | AA4: =Z4*3 -> 0 | AC4: ='CEB(UNCLASS)'!F23 -> 0 | AD4: =AC4*3 -> 0 | AF4: =SUM(B4,E4,H4,K4,N4,Q4,T4,W4, Z4,AC4) -> 0 | AG4: =AF4*3 -> 0 | AI4: PALLETS
A5: SHORT TONS | B5: ='RLT3 (UNCLASS)'!F24 -> 0 | C5: =B5*3 -> 0 | E5: ='RLT7(UNCLASS)'!F24 -> 0 | F5: =E5*3 -> 0 | H5: ='RLT4(UNCLASS)'!F24 -> 0 | I5: =H5*3 -> 0 | K5: ='12TH REG(UNCLASS)'!F24 -> 0 | L5: =K5*3 -> 0 | N5: ='HQBN(UNCLASS)'!F24 -> 0 | O5: =N5*3 -> 0 | Q5: ='LAR(UNCLASS)'!F24 -> 0 | R5: =Q5*3 -> 0 | T5: ='RECON(UNCLASS)'!F24 -> 0 | U5: =T5*3 -> 0 | W5: ='LE(UNCLASS)'!F24 -> 0 | X5: =W5*3 -> 0 | Z5: ='AATF(UNCLASS)'!F24 -> 0 | AA5: =Z5*3 -> 0 | AC5: ='CEB(UNCLASS)'!F24 -> 0 | AD5: =AC5*3 -> 0 | AF5: =SUM(B5,E5,H5,K5,N5,Q5,T5,W5,Z5,AC5) -> 0 | AG5: =AF5*3 -> 0 | AI5: SHORT TONS
A6: TEU (PALLET BASED) | B6: =B4/16 -> 0 | C6: =B6*3 -> 0 | E6: =E4/16 -> 0 | F6: =E6*3 -> 0 | H6: =H4/16 -> 0 | I6: =H6*3 -> 0 | K6: =K4/16 -> 0 | L6: =K6*3 -> 0 | N6: =N4/16 -> 0 | O6: =N6*3 -> 0 | Q6: =Q4/16 -> 0 | R6: =Q6*3 -> 0 | T6: =T4/16 -> 0 | U6: =T6*3 -> 0 | W6: =W4/16 -> 0 | X6: =W6*3 -> 0 | Z6: =Z4/16 -> 0 | AA6: =Z6*3 -> 0 | AC6: =AC4/16 -> 0 | AD6: =AC6*3 -> 0 | AF6: =SUM(B6,E6,H6,K6,N6,Q6,T6,W6,Z6,AC6) -> 0 | AG6: =AF6*3 -> 0 | AI6: TEU (PALLET BASED)
A7: CLASS I CHOW SUST RATE (3 M/M/D) | B7: 1 DOS | C7: 3 DOS | E7: 1 DOS | F7: 3 DOS | H7: 1 DOS | I7: 3 DOS | K7: 1 DOS | L7: 3 DOS | N7: 1 DOS | O7: 3 DOS | Q7: 1 DOS | R7: 3 DOS | T7: 1 DOS | U7: 3 DOS | W7: 1 DOS | X7: 3 DOS | Z7: 1 DOS | AA7: 3 DOS | AC7: 1 DOS | AD7: 3 DOS | AF7: 1 DOS | AG7: 3 DOS | AI7: CLASS I CHOW SUST RATE (3 M/M/D)
A8: PALLETS | B8: =B4 -> 0 | C8: =C4 -> 0 | E8: =E4 -> 0 | F8: =F4 -> 0 | H8: =H4 -> 0 | I8: =I4 -> 0 | K8: =K4 -> 0 | L8: =L4 -> 0 | N8: =N4 -> 0 | O8: =O4 -> 0 | Q8: =Q4 -> 0 | R8: =R4 -> 0 | T8: =T4 -> 0 | U8: =U4 -> 0 | W8: =W4 -> 0 | X8: =X4 -> 0 | Z8: =Z4 -> 0 | AA8: =AA4 -> 0 | AC8: =AC4 -> 0 | AD8: =AD4 -> 0 | AF8: =SUM(B8,E8,H8,K8,N8,Q8,T8,W8,Z8,AC8) -> 0 | AG8: =AF8*3 -> 0 | AI8: PALLETS
A9: SHORT TONS | B9: ='Summary (UNCLASS)'!B8*1098/2000 -> 0 | C9: =B9*3 -> 0 | E9: ='Summary (UNCLASS)'!E8*1098/2000 -> 0 | F9: =E9*3 -> 0 | H9: ='Summary (UNCLASS)'!H8*1098/2000 -> 0 | I9: =H9*3 -> 0 | K9: ='Summary (UNCLASS)'!K8*1098/2000 -> 0 | L9: =K9*3 -> 0 | N9: ='Summary (UNCLASS)'!N8*1098/2000 -> 0 | O9: =N9*3 -> 0 | Q9: ='Summary (UNCLASS)'!Q8*1098/2000 -> 0 | R9: =Q9*3 -> 0 | T9: ='Summary (UNCLASS)'!T8*1098/2000 -> 0 | U9: =T9*3 -> 0 | W9: ='Summary (UNCLASS)'!W8*1098/2000 -> 0 | X9: =W9*3 -> 0 | Z9: ='Summary (UNCLASS)'!Z8*1098/2000 -> 0 | AA9: =Z9*3 -> 0 | AC9: ='Summary (UNCLASS)'!AC8*1098/2000 -> 0 | AD9: =AC9*3 -> 0 | AF9: =SUM(B9,E9,H9,K9,N9,Q9,T9,W9,Z9,AC9) -> 0 | AG9: =AF9*3 -> 0 | AI9: SHORT TONS
A10: SB MTVR | B10: =B8/12 -> 0 | C10: =C8/12 -> 0 | E10: =E8/12 -> 0 | F10: =F8/12 -> 0 | H10: =H8/12 -> 0 | I10: =I8/12 -> 0 | K10: =K8/12 -> 0 | L10: =L8/12 -> 0 | N10: =N8/12 -> 0 | O10: =O8/12 -> 0 | Q10: =Q8/12 -> 0 | R10: =R8/12 -> 0 | T10: =T8/12 -> 0 | U10: =U8/12 -> 0 | W10: =W8/12 -> 0 | X10: =X8/12 -> 0 | Z10: =Z8/12 -> 0 | AA10: =AA8/12 -> 0 | AC10: =AC8/12 -> 0 | AD10: =AD8/12 -> 0 | AF10: =SUM(B10,E10,H10,K10,N10,Q10,T10,W10,Z10,AC10) -> 0 | AG10: =AF10*3 -> 0 | AI10: SB MTVR
A11: TEU (PALLET BASED) | B11: =B8/16 -> 0 | C11: =B11*3 -> 0 | E11: =E8/16 -> 0 | F11: =E11*3 -> 0 | H11: =H8/16 -> 0 | I11: =H11*3 -> 0 | K11: =K8/16 -> 0 | L11: =K11*3 -> 0 | N11: =N8/16 -> 0 | O11: =N11*3 -> 0 | Q11: =Q8/16 -> 0 | R11: =Q11*3 -> 0 | T11: =T8/16 -> 0 | U11: =T11*3 -> 0 | W11: =W8/16 -> 0 | X11: =W11*3 -> 0 | Z11: =Z8/16 -> 0 | AA11: =Z11*3 -> 0 | AC11: =AC8/16 -> 0 | AD11: =AC11*3 -> 0 | AF11: =SUM(B11,E11,H11,K11,N11,Q11,T11,W11,Z11,AC11) -> 0 | AG11: =AF11*3 -> 0 | AI11: TEU (PALLET BASED)
A12: CLASS I WATER ASLT RATE (2 GAL/M/D) | B12: 1 DOS | C12: 3 DOS | E12: 1 DOS | F12: 3 DOS | H12: 1 DOS | I12: 3 DOS | K12: 1 DOS | L12: 3 DOS | N12: 1 DOS | O12: 3 DOS | Q12: 1 DOS | R12: 3 DOS | T12: 1 DOS | U12: 3 DOS | W12: 1 DOS | X12: 3 DOS | Z12: 1 DOS | AA12: 3 DOS | AC12: 1 DOS | AD12: 3 DOS | AF12: 1 DOS | AG12: 3 DOS | AI12: CLASS I WATER ASLT RATE (2 GAL/M/D)
A13: GALLONS | B13: ='RLT3 (UNCLASS)'!F43 -> 0 | C13: =B13*3 -> 0 | E13: ='RLT7(UNCLASS)'!F43 -> 0 | F13: =E13*3 -> 0 | H13: ='RLT4(UNCLASS)'!F43 -> 0 | I13: =H13*3 -> 0 | K13: ='12TH REG(UNCLASS)'!F43 -> 0 | L13: =K13*3 -> 0 | N13: ='HQBN(UNCLASS)'!F43 -> 0 | O13: =N13*3 -> 0 | Q13: ='LAR(UNCLASS)'!F43 -> 0 | R13: =Q13*3 -> 0 | T13: ='RECON(UNCLASS)'!F43 -> 0 | U13: =T13*3 -> 0 | W13: ='LE(UNCLASS)'!F43 -> 0 | X13: =W13*3 -> 0 | Z13: ='AATF(UNCLASS)'!F43 -> 0 | AA13: =Z13*3 -> 0 | AC13: ='CEB(UNCLASS)'!F43 -> 0 | AD13: =AC13*3 -> 0 | AF13: =SUM(B13,E13,H13,K13,N13,Q13,T13,W13,Z13,AC13) -> 0 | AG13: =AF13*3 -> 0 | AI13: GALLONS
A14: SHORT TONS | B14: ='RLT3 (UNCLASS)'!F44 -> 0 | C14: =B14*3 -> 0 | E14: ='RLT7(UNCLASS)'!F44 -> 0 | F14: =E14*3 -> 0 | H14: ='RLT4(UNCLASS)'!F44 -> 0 | I14: =H14*3 -> 0 | K14: ='12TH REG(UNCLASS)'!F44 -> 0 | L14: =K14*3 -> 0 | N14: ='HQBN(UNCLASS)'!F44 -> 0 | O14: =N14*3 -> 0 | Q14: ='LAR(UNCLASS)'!F44 -> 0 | R14: =Q14*3 -> 0 | T14: ='RECON(UNCLASS)'!F44 -> 0 | U14: =T14*3 -> 0 | W14: ='LE(UNCLASS)'!F44 -> 0 | X14: =W14*3 -> 0 | Z14: ='AATF(UNCLASS)'!F44 -> 0 | AA14: =Z14*3 -> 0 | AC14: ='CEB(UNCLASS)'!F44 -> 0 | AD14: =AC14*3 -> 0 | AF14: =SUM(B14,E14,H14,K14,N14,Q14,T14,W14,Z14,AC14) -> 0 | AG14: =AF14*3 -> 0 | AI14: SHORT TONS
A15: SIXCON REQ (900 GAL PER) | B15: =B13/900 -> 0 | C15: =B15*3 -> 0 | E15: =E13/900 -> 0 | F15: =E15*3 -> 0 | H15: =H13/900 -> 0 | I15: =H15*3 -> 0 | K15: =K13/900 -> 0 | L15: =K15*3 -> 0 | N15: =N13/900 -> 0 | O15: =N15*3 -> 0 | Q15: =Q13/900 -> 0 | R15: =Q15*3 -> 0 | T15: =T13/900 -> 0 | U15: =T15*3 -> 0 | W15: =W13/900 -> 0 | X15: =W15*3 -> 0 | Z15: =Z13/900 -> 0 | AA15: =Z15*3 -> 0 | AC15: =AC13/900 -> 0 | AD15: =AC15*3 -> 0 | AF15: =SUM(B15,E15,H15,K15,N15,Q15,T15,W15,Z15,AC15) -> 0 | AG15: =AF15*3 -> 0 | AI15: SIXCON REQ (900 GAL PER)
A16: TEU (SIXCON BASE) | B16: =B15/4 -> 0 | C16: =B16*3 -> 0 | E16: =E15/4 -> 0 | F16: =E16*3 -> 0 | H16: =H15/4 -> 0 | I16: =H16*3 -> 0 | K16: =K15/4 -> 0 | L16: =K16*3 -> 0 | N16: =N15/4 -> 0 | O16: =N16*3 -> 0 | Q16: =Q15/4 -> 0 | R16: =Q16*3 -> 0 | T16: =T15/4 -> 0 | U16: =T16*3 -> 0 | W16: =W15/4 -> 0 | X16: =W16*3 -> 0 | Z16: =Z15/4 -> 0 | AA16: =Z16*3 -> 0 | AC16: =AC15/4 -> 0 | AD16: =AC16*3 -> 0 | AF16: =SUM(B16,E16,H16,K16,N16,Q16,T16,W16, Z16,AC16) -> 0 | AG16: =AF16*3 -> 0 | AI16: TEU (SIXCON BASE)
A17: CLASS I WATER SUST RATE (7 GAL/M/D) | B17: 1 DOS | C17: 3 DOS | E17: 1 DOS | F17: 3 DOS | H17: 1 DOS | I17: 3 DOS | K17: 1 DOS | L17: 3 DOS | N17: 1 DOS | O17: 3 DOS | Q17: 1 DOS | R17: 3 DOS | T17: 1 DOS | U17: 3 DOS | W17: 1 DOS | X17: 3 DOS | Z17: 1 DOS | AA17: 3 DOS | AC17: 1 DOS | AD17: 3 DOS | AF17: 1 DOS | AG17: 3 DOS | AI17: CLASS I WATER SUST RATE (7 GAL/M/D)
A18: GALLONS | B18: ='RLT3 (UNCLASS)'!F47 -> 0 | C18: =B18*3 -> 0 | E18: ='RLT7(UNCLASS)'!F47 -> 0 | F18: =E18*3 -> 0 | H18: ='RLT4(UNCLASS)'!F47 -> 0 | I18: =H18*3 -> 0 | K18: ='12TH REG(UNCLASS)'!F47 -> 0 | L18: =K18*3 -> 0 | N18: ='HQBN(UNCLASS)'!F47 -> 0 | O18: =N18*3 -> 0 | Q18: ='LAR(UNCLASS)'!F47 -> 0 | R18: =Q18*3 -> 0 | T18: ='RECON(UNCLASS)'!F47 -> 0 | U18: =T18*3 -> 0 | W18: ='LE(UNCLASS)'!F47 -> 0 | X18: =W18*3 -> 0 | Z18: ='AATF(UNCLASS)'!F47 -> 0 | AA18: =Z18*3 -> 0 | AC18: ='CEB(UNCLASS)'!F47 -> 0 | AD18: =AC18*3 -> 0 | AF18: =SUM(B18,E18,H18,K18,N18,Q18,T18,W18, Z18,AC18) -> 0 | AG18: =AF18*3 -> 0 | AI18: GALLONS
A19: SHORT TONS | B19: ='RLT3 (UNCLASS)'!F48 -> 0 | C19: =B19*3 -> 0 | E19: ='RLT7(UNCLASS)'!F48 -> 0 | F19: =E19*3 -> 0 | H19: ='RLT4(UNCLASS)'!F48 -> 0 | I19: =H19*3 -> 0 | K19: ='12TH REG(UNCLASS)'!F48 -> 0 | L19: =K19*3 -> 0 | N19: ='HQBN(UNCLASS)'!F48 -> 0 | O19: =N19*3 -> 0 | Q19: ='LAR(UNCLASS)'!F48 -> 0 | R19: =Q19*3 -> 0 | T19: ='RECON(UNCLASS)'!F48 -> 0 | U19: =T19*3 -> 0 | W19: ='LE(UNCLASS)'!F48 -> 0 | X19: =W19*3 -> 0 | Z19: ='AATF(UNCLASS)'!F48 -> 0 | AA19: =Z19*3 -> 0 | AC19: ='CEB(UNCLASS)'!F48 -> 0 | AD19: =AC19*3 -> 0 | AF19: =SUM(B19,E19,H19,K19,N19,Q19,T19,W19,Z19,AC19) -> 0 | AG19: =AF19*3 -> 0 | AI19: SHORT TONS
A20: SIXCON REQ (900 GAL PER) | B20: =B18/900 -> 0 | C20: =B20*3 -> 0 | E20: =E18/900 -> 0 | F20: =E20*3 -> 0 | H20: =H18/900 -> 0 | I20: =H20*3 -> 0 | K20: =K18/900 -> 0 | L20: =K20*3 -> 0 | N20: =N18/900 -> 0 | O20: =N20*3 -> 0 | Q20: =Q18/900 -> 0 | R20: =Q20*3 -> 0 | T20: =T18/900 -> 0 | U20: =T20*3 -> 0 | W20: =W18/900 -> 0 | X20: =W20*3 -> 0 | Z20: =Z18/900 -> 0 | AA20: =Z20*3 -> 0 | AC20: =AC18/900 -> 0 | AD20: =AC20*3 -> 0 | AF20: =SUM(B20,E20,H20,K20,N20,Q20,T20,W20,Z20,AC20) -> 0 | AG20: =AF20*3 -> 0 | AI20: SIXCON REQ (900 GAL PER)
A21: TEU (SIXCON BASE) | B21: =B20/4 -> 0 | C21: =B21*3 -> 0 | E21: =E20/4 -> 0 | F21: =E21*3 -> 0 | H21: =H20/4 -> 0 | I21: =H21*3 -> 0 | K21: =K20/4 -> 0 | L21: =K21*3 -> 0 | N21: =N20/4 -> 0 | O21: =N21*3 -> 0 | Q21: =Q20/4 -> 0 | R21: =Q21*3 -> 0 | T21: =T20/4 -> 0 | U21: =T21*3 -> 0 | W21: =W20/4 -> 0 | X21: =W21*3 -> 0 | Z21: =Z20/4 -> 0 | AA21: =Z21*3 -> 0 | AC21: =AC20/4 -> 0 | AD21: =AC21*3 -> 0 | AF21: =SUM(B21,E21,H21,K21,N21,Q21,T21,W21,Z21,AC21) -> 0 | AG21: =AF21*3 -> 0 | AI21: TEU (SIXCON BASE)
A22: CLASS II (NE ASIA RATE 2017 MSTP) | B22: 1 DOS | C22: 3 DOS | E22: 1 DOS | F22: 3 DOS | H22: 1 DOS | I22: 3 DOS | K22: 1 DOS | L22: 3 DOS | N22: 1 DOS | O22: 3 DOS | Q22: 1 DOS | R22: 3 DOS | T22: 1 DOS | U22: 3 DOS | W22: 1 DOS | X22: 3 DOS | Z22: 1 DOS | AA22: 3 DOS | AC22: 1 DOS | AD22: 3 DOS | AF22: 1 DOS | AG22: 3 DOS | AI22: CLASS II (NE ASIA RATE 2017 MSTP)
A23: SHORT TONS | B23: ='RLT3 (UNCLASS)'!F52 -> 0 | C23: =B23*3 -> 0 | E23: ='RLT7(UNCLASS)'!F52 -> 0 | F23: =E23*3 -> 0 | H23: ='RLT4(UNCLASS)'!F52 -> 0 | I23: =H23*3 -> 0 | K23: ='12TH REG(UNCLASS)'!F52 -> 0 | L23: =K23*3 -> 0 | N23: ='HQBN(UNCLASS)'!F52 -> 0 | O23: =N23*3 -> 0 | Q23: ='LAR(UNCLASS)'!F52 -> 0 | R23: =Q23*3 -> 0 | T23: ='RECON(UNCLASS)'!F52 -> 0 | U23: =T23*3 -> 0 | W23: ='LE(UNCLASS)'!F52 -> 0 | X23: =W23*3 -> 0 | Z23: ='AATF(UNCLASS)'!F52 -> 0 | AA23: =Z23*3 -> 0 | AC23: ='CEB(UNCLASS)'!F52 -> 0 | AD23: =AC23*3 -> 0 | AF23: =SUM(B23,E23,H23,K23,N23,Q23,T23,W23,Z23,AC23) -> 0 | AG23: =AF23*3 -> 0 | AI23: SHORT TONS
A24: TEU (MTVR BASED) | B24: ='RLT3 (UNCLASS)'!F53 -> 0 | C24: =B24*3 -> 0 | E24: ='RLT7(UNCLASS)'!F53 -> 0 | F24: =E24*3 -> 0 | H24: ='RLT4(UNCLASS)'!F53 -> 0 | I24: =H24*3 -> 0 | K24: ='12TH REG(UNCLASS)'!F53 -> 0 | L24: =K24*3 -> 0 | N24: ='HQBN(UNCLASS)'!F53 -> 0 | O24: =N24*3 -> 0 | Q24: ='LAR(UNCLASS)'!F53 -> 0 | R24: =Q24*3 -> 0 | T24: ='RECON(UNCLASS)'!F53 -> 0 | U24: =T24*3 -> 0 | W24: ='LE(UNCLASS)'!F53 -> 0 | X24: =W24*3 -> 0 | Z24: ='AATF(UNCLASS)'!F53 -> 0 | AA24: =Z24*3 -> 0 | AC24: ='CEB(UNCLASS)'!F53 -> 0 | AD24: =AC24*3 -> 0 | AF24: =SUM(B24,E24,H24,K24,N24,Q24,T24,W24,Z24,AC24) -> 0 | AG24: =AF24*3 -> 0 | AI24: TEU (MTVR BASED)
A25: CLASS III BULK FUEL BINGO | B25: 1 DOS | C25: 3 DOS | E25: 1 DOS | F25: 3 DOS | H25: 1 DOS | I25: 3 DOS | K25: 1 DOS | L25: 3 DOS | N25: 1 DOS | O25: 3 DOS | Q25: 1 DOS | R25: 3 DOS | T25: 1 DOS | U25: 3 DOS | W25: 1 DOS | X25: 3 DOS | Z25: 1 DOS | AA25: 3 DOS | AC25: 1 DOS | AD25: 3 DOS | AF25: 1 DOS | AG25: 3 DOS | AI25: CLASS III BULK FUEL BINGO
A26: GALLONS | B26: ='RLT3 (UNCLASS)'!F56 -> 0 | E26: ='RLT7(UNCLASS)'!F56 -> 0 | H26: ='RLT4(UNCLASS)'!F56 -> 0 | K26: ='12TH REG(UNCLASS)'!F56 -> 0 | N26: ='HQBN(UNCLASS)'!F56 -> 0 | Q26: ='LAR(UNCLASS)'!F56 -> 0 | T26: ='RECON(UNCLASS)'!F56 -> 0 | W26: ='LE(UNCLASS)'!F56 -> 0 | Z26: ='AATF(UNCLASS)'!F56 -> 0 | AC26: ='CEB(UNCLASS)'!F56 -> 0 | AF26: =SUM(B26,E26,H26,K26,N26,Q26,T26,W26,Z26,AC26) -> 0 | AG26: =SUM(C26,F26,I26,L26,O26,R26,U26,X26) -> 0 | AI26: GALLONS
A27: CLASS III BULK FUEL ASSAULT RATE | B27: 1 DOS | C27: 3 DOS | E27: 1 DOS | F27: 3 DOS | H27: 1 DOS | I27: 3 DOS | K27: 1 DOS | L27: 3 DOS | N27: 1 DOS | O27: 3 DOS | Q27: 1 DOS | R27: 3 DOS | T27: 1 DOS | U27: 3 DOS | W27: 1 DOS | X27: 3 DOS | Z27: 1 DOS | AA27: 3 DOS | AC27: 1 DOS | AD27: 3 DOS | AF27: 1 DOS | AG27: 3 DOS | AI27: CLASS III BULK FUEL ASSAULT RATE
A28: GALLONS | B28: ='RLT3 (UNCLASS)'!F59 -> 0 | C28: =B28*3 -> 0 | E28: ='RLT7(UNCLASS)'!F59 -> 0 | F28: =E28*3 -> 0 | H28: ='RLT4(UNCLASS)'!F59 -> 0 | I28: =H28*3 -> 0 | K28: ='12TH REG(UNCLASS)'!F59 -> 0 | L28: =K28*3 -> 0 | N28: ='HQBN(UNCLASS)'!F59 -> 0 | O28: =N28*3 -> 0 | Q28: ='LAR(UNCLASS)'!F59 -> 0 | R28: =Q28*3 -> 0 | T28: ='RECON(UNCLASS)'!F59 -> 0 | U28: =T28*3 -> 0 | W28: ='LE(UNCLASS)'!F59 -> 0 | X28: =W28*3 -> 0 | Z28: ='AATF(UNCLASS)'!F59 -> 0 | AA28: =Z28*3 -> 0 | AC28: ='CEB(UNCLASS)'!F59 -> 0 | AD28: =AC28*3 -> 0 | AF28: =SUM(B28,E28,H28,K28,N28,Q28,T28,W28,Z28,AC28) -> 0 | AG28: =AF28*3 -> 0 | AI28: GALLONS
A29: SHORT TONS | B29: ='RLT3 (UNCLASS)'!F60 -> 0 | C29: =B29*3 -> 0 | E29: ='RLT7(UNCLASS)'!F60 -> 0 | F29: =E29*3 -> 0 | H29: ='RLT4(UNCLASS)'!F60 -> 0 | I29: =H29*3 -> 0 | K29: ='12TH REG(UNCLASS)'!F60 -> 0 | L29: =K29*3 -> 0 | N29: ='HQBN(UNCLASS)'!F60 -> 0 | O29: =N29*3 -> 0 | Q29: ='LAR(UNCLASS)'!F60 -> 0 | R29: =Q29*3 -> 0 | T29: ='RECON(UNCLASS)'!F60 -> 0 | U29: =T29*3 -> 0 | W29: ='LE(UNCLASS)'!F60 -> 0 | X29: =W29*3 -> 0 | Z29: ='AATF(UNCLASS)'!F60 -> 0 | AA29: =Z29*3 -> 0 | AC29: ='CEB(UNCLASS)'!F60 -> 0 | AD29: =AC29*3 -> 0 | AF29: =SUM(B29,E29,H29,K29,N29,Q29,T29,W29,Z29,AC29) -> 0 | AG29: =AF29*3 -> 0 | AI29: SHORT TONS
A30: SIXCON REQ (850 GAL PER SIXCON) | B30: =B28/850 -> 0 | C30: =B30*3 -> 0 | E30: =E28/850 -> 0 | F30: =E30*3 -> 0 | H30: =H28/850 -> 0 | I30: =H30*3 -> 0 | K30: =K28/850 -> 0 | L30: =K30*3 -> 0 | N30: =N28/850 -> 0 | O30: =N30*3 -> 0 | Q30: =Q28/850 -> 0 | R30: =Q30*3 -> 0 | T30: =T28/850 -> 0 | U30: =T30*3 -> 0 | W30: =W28/850 -> 0 | X30: =W30*3 -> 0 | Z30: =Z28/850 -> 0 | AA30: =Z30*3 -> 0 | AC30: =AC28/850 -> 0 | AD30: =AC30*3 -> 0 | AF30: =SUM(B30,E30,H30,K30,N30,Q30,T30,W30,Z30,AC30) -> 0 | AG30: =AF30*3 -> 0 | AI30: SIXCON REQ (850 GAL PER SIXCON)
A31: FLAT RACK REFUELER REQ (2400 GAL PER FRC) | B31: =B28/2400 -> 0 | C31: =B31*3 -> 0 | E31: =E28/2400 -> 0 | F31: =E31*3 -> 0 | H31: =H28/2400 -> 0 | I31: =H31*3 -> 0 | K31: =K28/2400 -> 0 | L31: =K31*3 -> 0 | N31: =N28/2400 -> 0 | O31: =N31*3 -> 0 | Q31: =Q28/2400 -> 0 | R31: =Q31*3 -> 0 | T31: =T28/2400 -> 0 | U31: =T31*3 -> 0 | W31: =W28/2400 -> 0 | X31: =W31*3 -> 0 | Z31: =Z28/2400 -> 0 | AA31: =Z31*3 -> 0 | AC31: =AC28/2400 -> 0 | AD31: =AC31*3 -> 0 | AF31: =SUM(B31,E31,H31,K31,N31,Q31,T31,W31,Z31,AC31) -> 0 | AG31: =AF31*3 -> 0 | AI31: FLAT RACK REFUELER REQ (2400 GAL PER FRC)
A32: M970 REQ (4800 GAL PER M970) | B32: =B28/4900 -> 0 | C32: =B32*3 -> 0 | E32: =E28/4900 -> 0 | F32: =E32*3 -> 0 | H32: =H28/4900 -> 0 | I32: =H32*3 -> 0 | K32: =K28/4900 -> 0 | L32: =K32*3 -> 0 | N32: =N28/4900 -> 0 | O32: =N32*3 -> 0 | Q32: =Q28/4900 -> 0 | R32: =Q32*3 -> 0 | T32: =T28/4900 -> 0 | U32: =T32*3 -> 0 | W32: =W28/4900 -> 0 | X32: =W32*3 -> 0 | Z32: =Z28/4900 -> 0 | AA32: =Z32*3 -> 0 | AC32: =AC28/4900 -> 0 | AD32: =AC32*3 -> 0 | AF32: =SUM(B32,E32,H32,K32,N32,Q32,T32,W32,Z32,AC32) -> 0 | AG32: =AF32*3 -> 0 | AI32: M970 REQ (4800 GAL PER M970)
A33: CLASS III BULK FUEL SUSTAINED RATE | B33: 1 DOS | C33: 3 DOS | E33: 1 DOS | F33: 3 DOS | H33: 1 DOS | I33: 3 DOS | K33: 1 DOS | L33: 3 DOS | N33: 1 DOS | O33: 3 DOS | Q33: 1 DOS | R33: 3 DOS | T33: 1 DOS | U33: 3 DOS | W33: 1 DOS | X33: 3 DOS | Z33: 1 DOS | AA33: 3 DOS | AC33: 1 DOS | AD33: 3 DOS | AF33: 1 DOS | AG33: 3 DOS | AI33: CLASS III BULK FUEL SUSTAINED RATE
A34: GALLONS | B34: ='RLT3 (UNCLASS)'!F62 -> 0 | C34: =B34*3 -> 0 | E34: ='RLT7(UNCLASS)'!F62 -> 0 | F34: =E34*3 -> 0 | H34: ='RLT4(UNCLASS)'!F62 -> 0 | I34: =H34*3 -> 0 | K34: ='12TH REG(UNCLASS)'!F62 -> 0 | L34: =K34*3 -> 0 | N34: ='HQBN(UNCLASS)'!F62 -> 0 | O34: =N34*3 -> 0 | Q34: ='LAR(UNCLASS)'!F62 -> 0 | R34: =Q34*3 -> 0 | T34: ='RECON(UNCLASS)'!F62 -> 0 | U34: =T34*3 -> 0 | W34: ='LE(UNCLASS)'!F62 -> 0 | X34: =W34*3 -> 0 | Z34: ='AATF(UNCLASS)'!F62 -> 0 | AA34: =Z34*3 -> 0 | AC34: ='CEB(UNCLASS)'!F62 -> 0 | AD34: =AC34*3 -> 0 | AF34: =SUM(B34,E34,H34,K34,N34,Q34,T34,W34,Z34,AC34) -> 0 | AG34: =AF34*3 -> 0 | AI34: GALLONS
A35: SHORT TONS | B35: ='RLT3 (UNCLASS)'!F63 -> 0 | C35: =B35*3 -> 0 | E35: ='RLT7(UNCLASS)'!F63 -> 0 | F35: =E35*3 -> 0 | H35: ='RLT4(UNCLASS)'!F63 -> 0 | I35: =H35*3 -> 0 | K35: ='12TH REG(UNCLASS)'!F63 -> 0 | L35: =K35*3 -> 0 | N35: ='HQBN(UNCLASS)'!F63 -> 0 | O35: =N35*3 -> 0 | Q35: ='LAR(UNCLASS)'!F63 -> 0 | R35: =Q35*3 -> 0 | T35: ='RECON(UNCLASS)'!F63 -> 0 | U35: =T35*3 -> 0 | W35: ='LE(UNCLASS)'!F63 -> 0 | X35: =W35*3 -> 0 | Z35: ='AATF(UNCLASS)'!F63 -> 0 | AA35: =Z35*3 -> 0 | AC35: ='CEB(UNCLASS)'!F63 -> 0 | AD35: =AC35*3 -> 0 | AF35: =SUM(B35,E35,H35,K35,N35,Q35,T35,W35,Z35,AC35) -> 0 | AG35: =AF35*3 -> 0 | AI35: SHORT TONS
A36: SIXCON REQ (850 GAL PER SIXCON) | B36: =B34/850 -> 0 | C36: =B36*3 -> 0 | E36: =E34/850 -> 0 | F36: =E36*3 -> 0 | H36: =H34/850 -> 0 | I36: =H36*3 -> 0 | K36: =K34/850 -> 0 | L36: =K36*3 -> 0 | N36: =N34/850 -> 0 | O36: =N36*3 -> 0 | Q36: =Q34/850 -> 0 | R36: =Q36*3 -> 0 | T36: =T34/850 -> 0 | U36: =T36*3 -> 0 | W36: =W34/850 -> 0 | X36: =W36*3 -> 0 | Z36: =Z34/850 -> 0 | AA36: =Z36*3 -> 0 | AC36: =AC34/850 -> 0 | AD36: =AC36*3 -> 0 | AF36: =SUM(B36,E36,H36,K36,N36,Q36,T36,W36,Z36,AC36) -> 0 | AG36: =AF36*3 -> 0 | AI36: SIXCON REQ (850 GAL PER SIXCON)
A37: FLAT RACK REFUELER REQ (2400 GAL PER FRC) | B37: =B34/2400 -> 0 | C37: =B37*3 -> 0 | E37: =E34/2400 -> 0 | F37: =E37*3 -> 0 | H37: =H34/2400 -> 0 | I37: =H37*3 -> 0 | K37: =K34/2400 -> 0 | L37: =K37*3 -> 0 | N37: =N34/2400 -> 0 | O37: =N37*3 -> 0 | Q37: =Q34/2400 -> 0 | R37: =Q37*3 -> 0 | T37: =T34/2400 -> 0 | U37: =T37*3 -> 0 | W37: =W34/2400 -> 0 | X37: =W37*3 -> 0 | Z37: =Z34/2400 -> 0 | AA37: =Z37*3 -> 0 | AC37: =AC34/2400 -> 0 | AD37: =AC37*3 -> 0 | AF37: =SUM(B37,E37,H37,K37,N37,Q37,T37,W37,Z37,AC37) -> 0 | AG37: =AF37*3 -> 0 | AI37: FLAT RACK REFUELER REQ (2400 GAL PER FRC)
A38: M970 REQ (4800 GAL PER M970) | B38: =B34/4900 -> 0 | C38: =B38*3 -> 0 | E38: =E34/4900 -> 0 | F38: =E38*3 -> 0 | H38: =H34/4900 -> 0 | I38: =H38*3 -> 0 | K38: =K34/4900 -> 0 | L38: =K38*3 -> 0 | N38: =N34/4900 -> 0 | O38: =N38*3 -> 0 | Q38: =Q34/4900 -> 0 | R38: =Q38*3 -> 0 | T38: =T34/4900 -> 0 | U38: =T38*3 -> 0 | W38: =W34/4900 -> 0 | X38: =W38*3 -> 0 | Z38: =Z34/4900 -> 0 | AA38: =Z38*3 -> 0 | AC38: =AC34/4900 -> 0 | AD38: =AC38*3 -> 0 | AF38: =SUM(B38,E38,H38,K38,N38,Q38,T38,W38,Z38,AC38) -> 0 | AG38: =AF38*3 -> 0 | AI38: M970 REQ (4800 GAL PER M970)
A39: CLASS IV (NE ASIA RATE 2017 MSTP) | B39: 1 DOS | C39: 3 DOS | E39: 1 DOS | F39: 3 DOS | H39: 1 DOS | I39: 3 DOS | K39: 1 DOS | L39: 3 DOS | N39: 1 DOS | O39: 3 DOS | Q39: 1 DOS | R39: 3 DOS | T39: 1 DOS | U39: 3 DOS | W39: 1 DOS | X39: 3 DOS | Z39: 1 DOS | AA39: 3 DOS | AC39: 1 DOS | AD39: 3 DOS | AF39: 1 DOS | AG39: 3 DOS | AI39: CLASS IV (NE ASIA RATE 2017 MSTP)
A40: CL IV ST | B40: ='RLT3 (UNCLASS)'!F67 -> 0 | C40: =B40*3 -> 0 | E40: ='RLT7(UNCLASS)'!F67 -> 0 | F40: =E40*3 -> 0 | H40: ='RLT4(UNCLASS)'!F67 -> 0 | I40: =H40*3 -> 0 | K40: ='12TH REG(UNCLASS)'!F67 -> 0 | L40: =K40*3 -> 0 | N40: ='HQBN(UNCLASS)'!F67 -> 0 | O40: =N40*3 -> 0 | Q40: ='LAR(UNCLASS)'!F67 -> 0 | R40: =Q40*3 -> 0 | T40: ='RECON(UNCLASS)'!F67 -> 0 | U40: =T40*3 -> 0 | W40: ='LE(UNCLASS)'!F67 -> 0 | X40: =W40*3 -> 0 | Z40: ='AATF(UNCLASS)'!F67 -> 0 | AA40: =Z40*3 -> 0 | AC40: ='CEB(UNCLASS)'!F67 -> 0 | AD40: =AC40*3 -> 0 | AF40: =SUM(B40,E40,H40,K40,N40,Q40,T40,W40,Z40,AC40) -> 0 | AG40: =AF40*3 -> 0 | AI40: CL IV ST
...

Sheet EQUIP SUM (UNCLASS)
A1: EQUIPMENT SUMMARY
A2: TAMCN | B2: NOMEN | C2: EQUIP TYPE | D2: AAV BN | E2: ARTILLERY BN | F2: CAB | G2: CBT ENG BN | H2: HIMARS BN (5/11) | I2: INFANTRY BN | J2: LAR BN | K2: RECON BN | L2: TANK BN | M2: DIV HQ BN | N2: 3D MARINES HQ CO | O2: 4th MARINES HQ | P2: 7th MARINES HQ | Q2: 12 MARINES HQ BAT | R2: MPSRON 3 GUAM | S2: MPSRON 2 DG | T2: MPF TOTAL | U2: LE BATTALION | V2: w | W2: LENGTH | X2: WIDTH | Y2: HEIGHT | Z2: SQFT | AA2: CUBIC FEET | AB2: WT (GVW COMBAT LOADED) | AC2: FUEL CAPACITY | AD2: BURN RATE (MPG OR MPH) | AE2: CREW | AF2: PASSENGERS | AG2: FUEL PAYLOAD | AH2: WATER PAYLOAD | AI2: PAYLOAD | AJ2: PALLETS/PALCON | AK2: SIXCON TRANSSPO | AL2: QUADCON | AM2: ISCOCON | AN2: . | AO2: COMBAT LOAD PALLET | AP2: COMBAT LOAD PALLET WEIGHT | AQ2: ASLT RATE PALLET | AR2: ASLT RATE PALLET WEIGHT | AS2: SUSTAIN RATE PALLET | AT2: SUSTAIN RATE PALLET WEIGHT | AU2: . | AV2: UNITS/LCAC SPACE | AW2: UNITS/LCAC WEIGHT | AX2: LCACS LOADS (SQR OR WT OUT) | AY2: . | AZ2: UNITS/LCU SPACE | BA2: UNITS/LCU WEIGHT | BB2: TOTAL LCU
A3: A0067 | B3: MRC-148 (HF) (M1123 HMMWV ASSOICIATED) | C3: C2 VIC | D3: 2 | E3: 8 | F3: 4 | G3: 6 | H3: 6 | I3: 3 | J3: 3 | K3: 7 | L3: 3 | M3: 16 | N3: 5 | O3: 5 | P3: 5 | Q3: 9 | R3: 23 | S3: 23 | T3: =R3+S3 -> 46 | U3: 0 | W3: 182.5 | X3: 86 | Y3: 73.5 | Z3: =(W3/12)*(X3/12) -> 108.99306 | AA3: =(W3/12)*(X3/12)*(Y3/12) -> 667.58247 | AB3: 10300 | AC3: 25 | AD3: 11 | AE3: 2 | AF3: 0 | AG3: 0 | AH3: 0 | AI3: 4450 | AJ3: 1 | AK3: 0 | AL3: 0 | AM3: 0 | AO3: 0 | AP3: 0 | AQ3: 0 | AR3: 0 | AS3: 0 | AT3: 0 | AV3: =1809/Z3 -> 16.597388 | AW3: =120000/AB3 -> 11.650485 | AX3: =AB3/120000 -> 0.085833333 | AZ3: =1850/Z3 -> 16.973558 | BA3: =412000/AB3 -> 40 | BB3: =Z3/1850 -> 0.058915165
A4: A0153 | B4: MRC-142 (MULTI CH) (M1123 HMMWV ASSOICIATED) | C4: C2 VIC | D4: 0 | E4: 0 | F4: 0 | G4: 0 | H4: 0 | I4: 0 | J4: 0 | K4: 0 | L4: 0 | M4: 10 | N4: 4 | O4: 4 | P4: 4 | Q4: 4 | R4: 5 | S4: 5 | T4: =R4+S4 -> 10 | U4: 0 | W4: 182.5 | X4: 86 | Y4: 73.5 | Z4: =(W4/12)*(X4/12) -> 108.99306 | AA4: =(W4/12)*(X4/12)*(Y4/12) -> 667.58247 | AB4: 10300 | AC4: 25 | AD4: 11 | AE4: 2 | AF4: 0 | AG4: 0 | AH4: 0 | AI4: 4450 | AJ4: 1 | AK4: 0 | AL4: 0 | AM4: 0 | AO4: 0 | AP4: 0 | AQ4: 0 | AR4: 0 | AS4: 0 | AT4: 0 | AV4: =1809/Z4 -> 16.597388 | AW4: =120000/AB4 -> 11.650485 | AX4: =AB4/120000 -> 0.085833333 | AZ4: =1850/Z4 -> 16.973558 | BA4: =412000/AB4 -> 40 | BB4: =Z4/1850 -> 0.058915165
A5: A0403 | B5: MRC-145 (VHF RETRANS) (M1123 ASSOCIATED) | C5: C2 VIC | D5: 0 | E5: 9 | F5: 0 | G5: 0 | H5: 15 | I5: 5 | J5: 3 | K5: 6 | L5: 4 | M5: 15 | N5: 4 | O5: 4 | P5: 4 | Q5: 4 | R5: 0 | S5: 0 | T5: =R5+S5 -> 0 | U5: 0 | W5: 182.5 | X5: 86 | Y5: 73.5 | Z5: =(W5/12)*(X5/12) -> 108.99306 | AA5: =(W5/12)*(X5/12)*(Y5/12) -> 667.58247 | AB5: 10300 | AC5: 25 | AD5: 11 | AE5: 2 | AF5: 0 | AG5: 0 | AH5: 0 | AI5: 4450 | AJ5: 1 | AK5: 0 | AL5: 0 | AM5: 0 | AO5: 0 | AP5: 0 | AQ5: 0 | AR5: 0 | AS5: 0 | AT5: 0 | AV5: =1809/Z5 -> 16.597388 | AW5: =120000/AB5 -> 11.650485 | AX5: =AB5/120000 -> 0.085833333 | AZ5: =1850/Z5 -> 16.973558 | BA5: =412000/AB5 -> 40 | BB5: =Z5/1850 -> 0.058915165
A6: A1957 | B6: MRC-145 (VHF RETRANS (M1123 ASSOCIATED) | C6: C2 VIC | D6: 7 | E6: 20 | F6: 0 | G6: 5 | H6: 22 | I6: 5 | J6: 3 | K6: 0 | L6: 11 | M6: 24 | N6: 8 | O6: 8 | P6: 8 | Q6: 1 | R6: 53 | S6: 53 | T6: =R6+S6 -> 106 | U6: 0 | W6: 182.5 | X6: 86 | Y6: 73.5 | Z6: =(W6/12)*(X6/12) -> 108.99306 | AA6: =(W6/12)*(X6/12)*(Y6/12) -> 667.58247 | AB6: 10300 | AC6: 25 | AD6: 11 | AE6: 2 | AF6: 0 | AG6: 0 | AH6: 0 | AI6: 4450 | AJ6: 1 | AK6: 0 | AL6: 0 | AM6: 0 | AO6: 0 | AP6: 0 | AQ6: 0 | AR6: 0 | AS6: 0 | AT6: 0 | AV6: =1809/Z6 -> 16.597388 | AW6: =120000/AB6 -> 11.650485 | AX6: =AB6/120000 -> 0.085833333 | AZ6: =1850/Z6 -> 16.973558 | BA6: =412000/AB6 -> 40 | BB6: =Z6/1850 -> 0.058915165
A7: A0457 | B7: JLTV MRC-145B (NOT DELIVERED YET) | C7: C2 VIC | D7: 6 | E7: 11 | F7: 0 | G7: 3 | H7: 0 | I7: 5 | J7: 1 | K7: 2 | L7: 1 | M7: 12 | N7: 8 | O7: 8 | P7: 8 | Q7: 5 | R7: 0 | S7: 0 | T7: =R7+S7 -> 0 | U7: 0 | W7: 246.12 | X7: 98.4 | Y7: 102.36 | Z7: =(W7/12)*(X7/12) -> 168.182 | AA7: =(W7/12)*(X7/12)*(Y7/12) -> 1434.5925 | AB7: 19842 | AC7: 30 | AD7: 10 | AE7: 2 | AF7: 3 | AG7: 0 | AH7: 0 | AI7: 2000 | AJ7: 0.5 | AK7: 0 | AL7: 0 | AM7: 0 | AO7: 0 | AP7: 0 | AQ7: 0 | AR7: 0 | AS7: 0 | AT7: 0 | AV7: 0 | AW7: 0 | AX7: 0 | AZ7: 0 | BA7: 0 | BB7: 0
A8: A0458 | B8: JLTV MRC-148 (NOT DELIVERED YET) | C8: C2 VIC | D8: 1 | E8: 6 | F8: 2 | G8: 3 | H8: 0 | I8: 3 | J8: 1 | K8: 4 | L8: 1 | M8: 10 | N8: 5 | O8: 5 | P8: 5 | Q8: 5 | R8: 0 | S8: 0 | T8: =R8+S8 -> 0 | U8: 0 | W8: 246.12 | X8: 98.4 | Y8: 102.36 | Z8: =(W8/12)*(X8/12) -> 168.182 | AA8: =(W8/12)*(X8/12)*(Y8/12) -> 1434.5925 | AB8: 19842 | AC8: 30 | AD8: 10 | AE8: 2 | AF8: 3 | AG8: 0 | AH8: 0 | AI8: 2000 | AJ8: 0.5 | AK8: 0 | AL8: 0 | AM8: 0 | AO8: 0 | AP8: 0 | AQ8: 0 | AR8: 0 | AS8: 0 | AT8: 0 | AV8: 0 | AW8: 0 | AX8: 0 | AZ8: 0 | BA8: 0 | BB8: 0
A9: B0035 | B9: BUFFALO 6x6 | C9: MRAP | D9: 0 | E9: 0 | F9: 0 | G9: 3 | H9: 0 | I9: 0 | J9: 0 | K9: 0 | L9: 0 | M9: 0 | N9: 0 | O9: 0 | P9: 0 | Q9: 0 | R9: 1 | S9: 1 | T9: =R9+S9 -> 2 | U9: 0 | W9: 323 | X9: 106 | Y9: 156 | Z9: =(W9/12)*(X9/12) -> 237.76389 | AA9: =(W9/12)*(X9/12)*(Y9/12) -> 3090.9306 | AB9: 53500 | AC9: 85 | AD9: 3.8 | AE9: 2 | AF9: 4 | AG9: 0 | AH9: 0 | AI9: 22500 | AJ9: 0 | AK9: 0 | AL9: 0 | AM9: 0 | AO9: 0 | AP9: 0 | AQ9: 0 | AR9: 0 | AS9: 0 | AT9: 0 | AV9: =1809/Z9 -> 7.6083883 | AW9: =120000/AB9 -> 2.2429907 | AX9: =AB9/120000 -> 0.44583333 | AZ9: =1850/Z9 -> 7.7808283 | BA9: =412000/AB9 -> 7.7009346 | BB9: =AB9/412000 -> 0.12985437
A10: B0036 | B10: GRND EXP REFUEL SYSTEM, MED (GERS-M) | C10: FUEL | D10: 4 | E10: 0 | F10: 1 | G10: 4 | H10: 0 | I10: 0 | J10: 2 | K10: 0 | L10: 0 | M10: 6 | N10: 1 | O10: 1 | P10: 1 | Q10: 1 | R10: 4 | S10: 4 | T10: =R10+S10 -> 8 | U10: 0 | W10: 240 | X10: 240 | Y10: 120 | Z10: =(W10/12)*(X10/12) -> 400 | AA10: =(W10/12)*(X10/12)*(Y10/12) -> 4000 | AB10: 5173 | AC10: 620 | AD10: 0 | AE10: 0 | AF10: 0 | AG10: 620 | AH10: 0 | AI10: 0 | AJ10: 0 | AK10: 0 | AL10: 0 | AM10: 0 | AO10: 0 | AP10: 0 | AQ10: 0 | AR10: 0 | AS10: 0 | AT10: 0 | AV10: =1809/Z10 -> 4.5225 | AW10: =120000/AB10 -> 23.197371 | AX10: =Z10/1809 -> 0.22111664 | AZ10: =1850/Z10 -> 4.625 | BA10: =412000/AB10 -> 79.644307 | BB10: =Z10/1850 -> 0.21621622
A11: B0037 | B11: GRND EXP REFUEL SYSTEM, SMALL (GERS-S) | C11: FUEL | D11: 4 | E11: 0 | F11: 1 | G11: 4 | H11: 0 | I11: 0 | J11: 2 | K11: 0 | L11: 0 | M11: 6 | N11: 1 | O11: 1 | P11: 1 | Q11: 1 | R11: 4 | S11: 4 | T11: =R11+S11 -> 8 | U11: 0 | W11: 240 | X11: 180 | Y11: 120 | Z11: =(W11/12)*(X11/12) -> 300 | AA11: =(W11/12)*(X11/12)*(Y11/12) -> 3000 | AB11: 1730 | AC11: 168 | AD11: 0 | AE11: 0 | AF11: 0 | AG11: 168 | AH11: 0 | AI11: 0 | AJ11: 0 | AK11: 0 | AL11: 0 | AM11: 0 | AO11: 0 | AP11: 0 | AQ11: 0 | AR11: 0 | AS11: 0 | AT11: 0 | AV11: =1809/Z11 -> 6.03 | AW11: =120000/AB11 -> 69.364162 | AX11: =Z11/1809 -> 0.16583748 | AZ11: =1850/Z11 -> 6.1666667 | BA11: =412000/AB11 -> 238.15029 | BB11: =Z11/1850 -> 0.16216216
A12: B0040 | B12: MULTI-TERRAIN LOADER (MTL) | C12: HE | D12: 0 | E12: 0 | F12: 4 | G12: 18 | H12: 0 | I12: 0 | J12: 0 | K12: 0 | L12: 0 | M12: 0 | N12: 0 | O12: 0 | P12: 0 | Q12: 4 | R12: 2 | S12: 2 | T12: =R12+S12 -> 4 | U12: 0 | W12: 78 | X12: 150 | Y12: 82 | Z12: =(W12/12)*(X12/12) -> 81.25 | AA12: =(W12/12)*(X12/12)*(Y12/12) -> 555.20833 | AB12: 9958 | AC12: 20 | AD12: 3 | AE12: 1 | AF12: 0 | AG12: 0 | AH12: 0 | AI12: 0 | AJ12: 0 | AK12: 0 | AL12: 0 | AM12: 0 | AO12: 0 | AP12: 0 | AQ12: 0 | AR12: 0 | AS12: 0 | AT12: 0 | AV12: =1809/Z12 -> 22.264615 | AW12: =120000/AB12 -> 12.050613 | AX12: =AB12/120000 -> 0.082983333 | AZ12: =1850/Z12 -> 22.769231 | BA12: =412000/AB12 -> 41.37377 | BB12: =Z12/1850 -> 0.043918919
A13: B0043 | B13: GENERATOR 15KW MEP1050 | C13: UT | D13: 0 | E13: 4 | F13: 16 | G13: 36 | H13: 0 | I13: 0 | J13: 6 | K13: 0 | L13: 2 | M13: 10 | N13: 0 | O13: 0 | P13: 0 | Q13: 10 | R13: 0 | S13: 11 | T13: =R13+S13 -> 11 | U13: 0 | W13: 65 | X13: 36 | Y13: 52 | Z13: =(W13/12)*(X13/12) -> 16.25 | AA13: =(W13/12)*(X13/12)*(Y13/12) -> 70.416667 | AB13: 1610 | AC13: 8.61 | AD13: 0.77 | AE13: 0 | AF13: 0 | AG13: 0 | AH13: 0 | AI13: 0 | AJ13: 0 | AK13: 0 | AL13: 0 | AM13: 0 | AO13: 0 | AP13: 0 | AQ13: 0 | AR13: 0 | AS13: 0 | AT13: 0 | AV13: =1809/Z13 -> 111.32308 | AW13: =120000/AB13 -> 74.534161 | AX13: =AB13/120000 -> 0.013416667 | AZ13: =1850/Z13 -> 113.84615 | BA13: =412000/AB13 -> 255.90062 | BB13: =Z13/1850 -> 0.0087837838
A14: B0055 | B14: BATH UNIT, PORTABLE | C14: UT | D14: 0 | E14: 0 | F14: 4 | G14: 0 | H14: 0 | I14: 0 | J14: 0 | K14: 0 | L14: 0 | M14: 0 | N14: 0 | O14: 0 | P14: 0 | Q14: 0 | R14: 0 | S14: 0 | T14: =R14+S14 -> 0 | U14: 0 | W14: 216 | X14: 72 | Y14: 72 | Z14: =(W14/12)*(X14/12) -> 108 | AA14: =(W14/12)*(X14/12)*(Y14/12) -> 648 | AB14: 1617 | AC14: 5 | AD14: 1 | AE14: 0 | AF14: 0 | AG14: 0 | AH14: 0 | AI14: 0 | AJ14: 0 | AK14: 0 | AL14: 0 | AM14: 0 | AO14: 0 | AP14: 0 | AQ14: 0 | AR14: 0 | AS14: 0 | AT14: 0 | AV14: =1809/Z14 -> 16.75 | AW14: =120000/AB14 -> 74.211503 | AX14: =Z14/1809 -> 0.059701493 | AZ14: =1850/Z14 -> 17.12963 | BA14: =412000/AB14 -> 254.79283 | BB14: =Z14/1850 -> 0.058378378
A15: B0060 | B15: MEDIUM CRAWER TRACTOR (MCT) JOHN DEER | C15: HE | D15: 0 | E15: 0 | F15: 3 | G15: 5 | H15: 0 | I15: 0 | J15: 0 | K15: 0 | L15: 0 | M15: 0 | N15: 0 | O15: 0 | P15: 0 | Q15: 6 | R15: 5 | S15: 5 | T15: =R15+S15 -> 10 | U15: 0 | W15: 258 | X15: 140 | Y15: 131 | Z15: =(W15/12)*(X15/12) -> 250.83333 | AA15: =(W15/12)*(X15/12)*(Y15/12) -> 2738.2639 | AB15: 49900 | AC15: 56 | AD15: 7 | AE15: 1 | AF15: 0 | AG15: 0 | AH15: 0 | AI15: 0 | AJ15: 0 | AK15: 0 | AL15: 0 | AM15: 0 | AO15: 0 | AP15: 0 | AQ15: 0 | AR15: 0 | AS15: 0 | AT15: 0 | AV15: =1809/Z15 -> 7.2119601 | AW15: =120000/AB15 -> 2.4048096 | AX15: =AB15/120000 -> 0.41583333 | AZ15: =1850/Z15 -> 7.3754153 | BA15: =412000/AB15 -> 8.256513 | BB15: =Z15/1850 -> 0.13558559
A16: B0063 | B16: TRAM 10K FORKLIFT | C16: MHE | D16: 1 | E16: 0 | F16: 6 | G16: 10 | H16: 0 | I16: 0 | J16: 1 | K16: 0 | L16: 1 | M16: 0 | N16: 0 | O16: 0 | P16: 0 | Q16: 8 | R16: 11 | S16: 10 | T16: =R16+S16 -> 21 | U16: 0 | W16: 346 | X16: 104 | Y16: 132 | Z16: =(W16/12)*(X16/12) -> 249.88889 | AA16: =(W16/12)*(X16/12)*(Y16/12) -> 2748.7778 | AB16: 40700 | AC16: 64 | AD16: 8 | AE16: 1 | AF16: 0 | AG16: 0 | AH16: 0 | AI16: 0 | AJ16: 0 | AK16: 0 | AL16: 0 | AM16: 0 | AO16: 0 | AP16: 0 | AQ16: 0 | AR16: 0 | AS16: 0 | AT16: 0 | AV16: =1809/Z16 -> 7.2392174 | AW16: =120000/AB16 -> 2.9484029 | AX16: =AB16/120000 -> 0.33916667 | AZ16: =1850/Z16 -> 7.4032904 | BA16: =412000/AB16 -> 10.12285 | BB16: =Z16/1850 -> 0.13507508
A17: B0066 | B17: CONTAINERIZED BATCH LAUNDRY UNIT (CBU) | C17: UT | D17: 0 | E17: 0 | F17: 2 | G17: 0 | H17: 0 | I17: 0 | J17: 0 | K17: 0 | L17: 0 | M17: 0 | N17: 0 | O17: 0 | P17: 0 | Q17: 0 | R17: 0 | S17: 0 | T17: =R17+S17 -> 0 | U17: 0 | W17: 260 | X17: 96 | Y17: 96 | Z17: =(W17/12)*(X17/12) -> 173.33333 | AA17: =(W17/12)*(X17/12)*(Y17/12) -> 1386.6667 | AB17: 11600 | AC17: 0 | AD17: 0 | AE17: 0 | AF17: 0 | AG17: 0 | AH17: 0 | AI17: 0 | AJ17: 0 | AK17: 0 | AL17: 0 | AM17: 0 | AO17: 0 | AP17: 0 | AQ17: 0 | AR17: 0 | AS17: 0 | AT17: 0 | AV17: =1809/Z17 -> 10.436538 | AW17: =120000/AB17 -> 10.344828 | AX17: =AB17/120000 -> 0.096666667 | AZ17: =1850/Z17 -> 10.673077 | BA17: =412000/AB17 -> 35.517241 | BB17: =Z17/1850 -> 0.093693694
A18: B0071 | B18: LTWT WATER PUR SYS (LWPS) | C18: UT | D18: 0 | E18: 0 | F18: 2 | G18: 0 | H18: 0 | I18: 0 | J18: 0 | K18: 0 | L18: 0 | M18: 0 | N18: 0 | O18: 0 | P18: 0 | Q18: 0 | R18: 0 | S18: 0 | T18: =R18+S18 -> 0 | U18: 0 | W18: 78 | X18: 48 | Y18: 37 | Z18: =(W18/12)*(X18/12) -> 26 | AA18: =(W18/12)*(X18/12)*(Y18/12) -> 80.166667 | AB18: 912 | AC18: 3 | AD18: 0.5 | AE18: 0 | AF18: 0 | AG18: 0 | AH18: 0 | AI18: 0 | AJ18: 0 | AK18: 0 | AL18: 0 | AM18: 0 | AO18: 0 | AP18: 0 | AQ18: 0 | AR18: 0 | AS18: 0 | AT18: 0 | AV18: =1809/Z18 -> 69.576923 | AW18: =120000/AB18 -> 131.57895 | AX18: =Z18/1809 -> 0.014372582 | AZ18: =1850/Z18 -> 71.153846 | BA18: =412000/AB18 -> 451.75439 | BB18: =Z18/1850 -> 0.014054054
A19: B0075 | B19: SMALL FIELD REFRIGERATION SYS (SFRS) | C19: UT | D19: 0 | E19: 0 | F19: 2 | G19: 2 | H19: 0 | I19: 0 | J19: 2 | K19: 0 | L19: 0 | M19: 2 | N19: 2 | O19: 2 | P19: 2 | Q19: 0 | R19: 9 | S19: 9 | T19: =R19+S19 -> 18 | U19: 0 | W19: 77 | X19: 96 | Y19: 96 | Z19: =(W19/12)*(X19/12) -> 51.333333 | AA19: =(W19/12)*(X19/12)*(Y19/12) -> 410.66667 | AB19: 3900 | AC19: 0 | AD19: 0 | AE19: 0 | AF19: 0 | AG19: 0 | AH19: 0 | AI19: 0 | AJ19: 0 | AK19: 0 | AL19: 0 | AM19: 0 | AO19: 0 | AP19: 0 | AQ19: 0 | AR19: 0 | AS19: 0 | AT19: 0 | AV19: =1809/Z19 -> 35.24026 | AW19: =120000/AB19 -> 30.769231 | AX19: =AB19/120000 -> 0.0325 | AZ19: =1850/Z19 -> 36.038961 | BA19: =412000/AB19 -> 105.64103 | BB19: =Z19/1850 -> 0.027747748
A20: B0077 | B20: GENERATOR 5KW MEP 802 | C20: UT | D20: 2 | E20: 2 | F20: 10 | G20: 16 | H20: 0 | I20: 0 | J20: 4 | K20: 0 | L20: 5 | M20: 8 | N20: 0 | O20: 0 | P20: 0 | Q20: 32 | R20: 0 | S20: 8 | T20: =R20+S20 -> 8 | U20: 0 | W20: 50 | X20: 31 | Y20: 36 | Z20: =(W20/12)*(X20/12) -> 10.763889 | AA20: =(W20/12)*(X20/12)*(Y20/12) -> 32.291667 | AB20: 888 | AC20: 5 | AD20: 0.57 | AE20: 0 | AF20: 0 | AG20: 0 | AH20: 0 | AI20: 0 | AJ20: 0 | AK20: 0 | AL20: 0 | AM20: 0 | AO20: 0 | AP20: 0 | AQ20: 0 | AR20: 0 | AS20: 0 | AT20: 0 | AV20: =1809/Z20 -> 168.06194 | AW20: =120000/AB20 -> 135.13514 | AX20: =AB20/120000 -> 0.0074 | AZ20: =1850/Z20 -> 171.87097 | BA20: =412000/AB20 -> 463.96396 | BB20: =Z20/1850 -> 0.0058183183
A21: B0078 | B21: GRADER | C21: HE | D21: 0 | E21: 0 | F21: 2 | G21: 2 | H21: 0 | I21: 0 | J21: 0 | K21: 0 | L21: 0 | M21: 0 | N21: 0 | O21: 0 | P21: 0 | Q21: 0 | R21: 1 | S21: 1 | T21: =R21+S21 -> 2 | U21: 0 | W21: 352 | X21: 105 | Y21: 129 | Z21: =(W21/12)*(X21/12) -> 256.66667 | AA21: =(W21/12)*(X21/12)*(Y21/12) -> 2759.1667 | AB21: 44000 | AC21: 24 | AD21: 4 | AE21: 1 | AF21: 0 | AG21: 0 | AH21: 0 | AI21: 0 | AJ21: 0 | AK21: 0 | AL21: 0 | AM21: 0 | AO21: 0 | AP21: 0 | AQ21: 0 | AR21: 0 | AS21: 0 | AT21: 0 | AV21: =1809/Z21 -> 7.0480519 | AW21: =120000/AB21 -> 2.7272727 | AX21: =AB21/120000 -> 0.36666667 | AZ21: =1850/Z21 -> 7.2077922 | BA21: =412000/AB21 -> 9.3636364 | BB21: =Z21/1850 -> 0.13873874
A22: B0093 | B22: HUSKY VMMD (ARMY-POR) | C22: MRAP | D22: 0 | E22: 0 | F22: 0 | G22: 0 | H22: 0 | I22: 0 | J22: 0 | K22: 0 | L22: 0 | M22: 0 | N22: 0 | O22: 0 | P22: 0 | Q22: 0 | R22: 0 | S22: 2 | T22: =R22+S22 -> 2 | U22: 0 | W22: 288.9 | X22: 99.5 | Y22: 139.3 | Z22: =(W22/12)*(X22/12) -> 199.62187 | AA22: =(W22/12)*(X22/12)*(Y22/12) -> 2317.2773 | AB22: 23000 | AC22: 30 | AD22: 10 | AE22: 1 | AF22: 0 | AG22: 0 | AH22: 0 | AI22: 0 | AJ22: 0 | AK22: 0 | AL22: 0 | AM22: 0 | AO22: 0 | AP22: 0 | AQ22: 0 | AR22: 0 | AS22: 0 | AT22: 0 | AV22: =1809/Z22 -> 9.0621331 | AW22: =120000/AB22 -> 5.2173913 | AX22: =AB22/120000 -> 0.19166667 | AZ22: =1850/Z22 -> 9.2675214 | BA22: =412000/AB22 -> 17.913043 | BB22: =Z22/1850 -> 0.10790372
A23: B0160 | B23: ASSAULT BREACHER VEHICLE (ABV) | C23: ABV | D23: 0 | E23: 0 | F23: 0 | G23: 8 | H23: 0 | I23: 0 | J23: 0 | K23: 0 | L23: 0 | M23: 0 | N23: 0 | O23: 0 | P23: 0 | Q23: 0 | R23: 5 | S23: 5 | T23: =R23+S23 -> 10 | U23: 0 | W23: 316 | X23: 173 | Y23: 172 | Z23: =(W23/12)*(X23/12) -> 379.63889 | AA23: =(W23/12)*(X23/12)*(Y23/12) -> 5441.4907 | AB23: 125420 | AC23: 505 | AD23: 0.6 | AE23: 4 | AF23: 0 | AG23: 0 | AH23: 0 | AI23: 0 | AJ23: 0 | AK23: 0 | AL23: 0 | AM23: 0 | AO23: 0 | AP23: 0 | AQ23: 0 | AR23: 0 | AS23: 0 | AT23: 0 | AV23: =1809/Z23 -> 4.7650545 | AW23: =120000/AB23 -> 0.9567852 | AX23: =AB23/120000 -> 1.0451667 | AZ23: =1850/Z23 -> 4.8730519 | BA23: =412000/AB23 -> 3.2849625 | BB23: =AB23/412000 -> 0.30441748
A24: B0472 | B24: DEMOLITION SET, EXPLOSIVE | C24: ENG | D24: 0 | E24: 0 | F24: 0 | G24: 108 | H24: 13 | I24: 0 | J24: 0 | K24: 0 | L24: 0 | M24: 0 | N24: 0 | O24: 0 | P24: 0 | Q24: 0 | R24: 13 | S24: 13 | T24: =R24+S24 -> 26 | U24: 0 | W24: 0 | X24: 0 | Y24: 0 | Z24: =(W24/12)*(X24/12) -> 0 | AA24: =(W24/12)*(X24/12)*(Y24/12) -> 0 | AB24: 0 | AC24: 0 | AD24: 0 | AE24: 0 | AF24: 0 | AG24: 0 | AH24: 0 | AI24: 0 | AJ24: 0 | AK24: 0 | AL24: 0 | AM24: 0 | AO24: 0 | AP24: 0 | AQ24: 0 | AR24: 0 | AS24: 0 | AT24: 0 | AV24: 0 | AW24: 0 | AX24: 0 | AZ24: 0 | BA24: 0 | BB24: 0
A25: B0589 | B25: ARMORED COMBAT EARTHMOVER M9 (ACE) | C25: HE | D25: 0 | E25: 0 | F25: 8 | G25: 12 | H25: 0 | I25: 0 | J25: 0 | K25: 0 | L25: 0 | M25: 0 | N25: 0 | O25: 0 | P25: 0 | Q25: 0 | R25: 3 | S25: 3 | T25: =R25+S25 -> 6 | U25: 0 | W25: 253 | X25: 126 | Y25: 107 | Z25: =(W25/12)*(X25/12) -> 221.375 | AA25: =(W25/12)*(X25/12)*(Y25/12) -> 1973.9271 | AB25: 54000 | AE25: 1 | AF25: 0 | AG25: 0 | AH25: 0 | AI25: 0 | AJ25: 0 | AK25: 0 | AL25: 0 | AM25: 0 | AO25: 0 | AP25: 0 | AQ25: 0 | AR25: 0 | AS25: 0 | AT25: 0 | AV25: =1809/Z25 -> 8.1716544 | AW25: =120000/AB25 -> 2.2222222 | AX25: =AB25/120000 -> 0.45 | AZ25: =1850/Z25 -> 8.3568605 | BA25: =412000/AB25 -> 7.6296296 | BB25: =AB25/412000 -> 0.13106796
A26: B0640 | B26: FLOODLIGHT SET | C26: UT | D26: 0 | E26: 1 | F26: 3 | G26: 5 | H26: 0 | I26: 0 | J26: 3 | K26: 0 | L26: 1 | M26: 3 | N26: 0 | O26: 0 | P26: 0 | Q26: 5 | R26: 10 | S26: 10 | T26: =R26+S26 -> 20 | U26: 0 | W26: 127 | X26: 46 | Y26: 60 | Z26: =(W26/12)*(X26/12) -> 40.569444 | AA26: =(W26/12)*(X26/12)*(Y26/12) -> 202.84722 | AB26: 1862 | AC26: 6.5 | AD26: 0.5 | AE26: 0 | AF26: 0 | AG26: 0 | AH26: 0 | AI26: 0 | AJ26: 0 | AK26: 0 | AL26: 0 | AM26: 0 | AO26: 0 | AP26: 0 | AQ26: 0 | AR26: 0 | AS26: 0 | AT26: 0 | AV26: =1809/Z26 -> 44.590209 | AW26: =120000/AB26 -> 64.446831 | AX26: =Z26/1809 -> 0.022426448 | AZ26: =1850/Z26 -> 45.600822 | BA26: =412000/AB26 -> 221.26745 | BB26: =Z26/1850 -> 0.021929429
A27: B0730 | B27: GENERATOR 3KW MEP 831 | C27: UT | D27: 6 | E27: 0 | F27: 12 | G27: 0 | H27: 0 | I27: 0 | J27: 12 | K27: 0 | L27: 0 | M27: 12 | N27: 6 | O27: 6 | P27: 6 | Q27: 12 | R27: 18 | S27: 18 | T27: =R27+S27 -> 36 | U27: 0 | W27: 35 | X27: 28 | Y27: 27 | Z27: =(W27/12)*(X27/12) -> 6.8055556 | AA27: =(W27/12)*(X27/12)*(Y27/12) -> 15.3125 | AB27: 334 | AC27: 4 | AD27: 0.5 | AE27: 0 | AF27: 0 | AG27: 0 | AH27: 0 | AI27: 0 | AJ27: 0 | AK27: 0 | AL27: 0 | AM27: 0 | AO27: 0 | AP27: 0 | AQ27: 0 | AR27: 0 | AS27: 0 | AT27: 0 | AV27: =1809/Z27 -> 265.81224 | AW27: =120000/AB27 -> 359.28144 | AX27: =Z27/1809 -> 0.0037620539 | AZ27: =1850/Z27 -> 271.83673 | BA27: =412000/AB27 -> 1233.5329 | BB27: =Z27/1850 -> 0.0036786787
A28: B0891 | B28: GENERATOR 10KW MEP 803 | C28: UT | D28: 4 | E28: 4 | F28: 8 | G28: 16 | H28: 0 | I28: 0 | J28: 4 | K28: 0 | L28: 6 | M28: 6 | N28: 0 | O28: 0 | P28: 0 | Q28: 8 | R28: 8 | S28: 8 | T28: =R28+S28 -> 16 | U28: 0 | W28: 62 | X28: 32 | Y28: 37 | Z28: =(W28/12)*(X28/12) -> 13.777778 | AA28: =(W28/12)*(X28/12)*(Y28/12) -> 42.481481 | AB28: 1242 | AC28: 9 | AD28: 1 | AE28: 0 | AF28: 0 | AG28: 0 | AH28: 0 | AI28: 0 | AJ28: 0 | AK28: 0 | AL28: 0 | AM28: 0 | AO28: 0 | AP28: 0 | AQ28: 0 | AR28: 0 | AS28: 0 | AT28: 0 | AV28: =1809/Z28 -> 131.29839 | AW28: =120000/AB28 -> 96.618357 | AX28: =AB28/120000 -> 0.01035 | AZ28: =1850/Z28 -> 134.27419 | BA28: =412000/AB28 -> 331.72303 | BB28: =Z28/1850 -> 0.0074474474
A29: B0921 | B29: GENERATOR 10KW MEP 813 | C29: UT | D29: 0 | E29: 0 | F29: 0 | G29: 0 | H29: 0 | I29: 0 | J29: 0 | K29: 0 | L29: 0 | M29: 0 | N29: 0 | O29: 0 | P29: 0 | Q29: 6 | R29: 0 | S29: 0 | T29: =R29+S29 -> 0 | U29: 0 | W29: 62 | X29: 32 | Y29: 37 | Z29: =(W29/12)*(X29/12) -> 13.777778 | AA29: =(W29/12)*(X29/12)*(Y29/12) -> 42.481481 | AB29: 1272 | AC29: 9 | AD29: 1 | AE29: 0 | AF29: 0 | AG29: 0 | AH29: 0 | AI29: 0 | AJ29: 0 | AK29: 0 | AL29: 0 | AM29: 0 | AO29: 0 | AP29: 0 | AQ29: 0 | AR29: 0 | AS29: 0 | AT29: 0 | AV29: =1809/Z29 -> 131.29839 | AW29: =120000/AB29 -> 94.339623 | AX29: =AB29/120000 -> 0.0106 | AZ29: =1850/Z29 -> 134.27419 | BA29: =412000/AB29 -> 323.89937 | BB29: =Z29/1850 -> 0.0074474474
A30: B0953 | B30: GENERATOR 30KW MEP 1060 | C30: UT | D30: 2 | E30: 2 | F30: 10 | G30: 24 | H30: 0 | I30: 0 | J30: 2 | K30: 0 | L30: 2 | M30: 11 | N30: 0 | O30: 0 | P30: 0 | Q30: 10 | R30: 3 | S30: 0 | T30: =R30+S30 -> 3 | U30: 0 | W30: 75 | X30: 36 | Y30: 52 | Z30: =(W30/12)*(X30/12) -> 18.75 | AA30: =(W30/12)*(X30/12)*(Y30/12) -> 81.25 | AB30: 2330 | AC30: 16 | AD30: 1.5 | AE30: 0 | AF30: 0 | AG30: 0 | AH30: 0 | AI30: 0 | AJ30: 0 | AK30: 0 | AL30: 0 | AM30: 0 | AO30: 0 | AP30: 0 | AQ30: 0 | AR30: 0 | AS30: 0 | AT30: 0 | AV30: =1809/Z30 -> 96.48 | AW30: =120000/AB30 -> 51.502146 | AX30: =AB30/120000 -> 0.019416667 | AZ30: =1850/Z30 -> 98.666667 | BA30: =412000/AB30 -> 176.82403 | BB30: =Z30/1850 -> 0.010135135
A31: B0980 | B31: GENERATOR 2KW MEP531 MAN-LIFT | C31: UT | D31: 0 | E31: 0 | F31: 2 | G31: 0 | H31: 0 | I31: 0 | J31: 0 | K31: 2 | L31: 0 | M31: 4 | N31: 0 | O31: 0 | P31: 0 | Q31: 0 | R31: 5 | S31: 5 | T31: =R31+S31 -> 10 | U31: 0 | W31: 29.5 | X31: 16 | Y31: 21.7 | Z31: =(W31/12)*(X31/12) -> 3.2777778 | AA31: =(W31/12)*(X31/12)*(Y31/12) -> 5.9273148 | AB31: 152 | AC31: 1.6 | AD31: 0.3 | AE31: 0 | AF31: 0 | AG31: 0 | AH31: 0 | AI31: 0 | AJ31: 0 | AK31: 0 | AL31: 0 | AM31: 0 | AO31: 0 | AP31: 0 | AQ31: 0 | AR31: 0 | AS31: 0 | AT31: 0 | AV31: =1809/Z31 -> 551.89831 | AW31: =120000/AB31 -> 789.47368 | AX31: =Z31/1809 -> 0.001811928 | AZ31: =1850/Z31 -> 564.40678 | BA31: =412000/AB31 -> 2710.5263 | BB31: =Z31/1850 -> 0.0017717718
A32: B1021 | B32: GENERATOR 60KW MEP806 | C32: UT | D32: 1 | E32: 0 | F32: 10 | G32: 15 | H32: 0 | I32: 0 | J32: 0 | K32: 0 | L32: 0 | M32: 4 | N32: 0 | O32: 0 | P32: 0 | Q32: 4 | R32: 1 | S32: 2 | T32: =R32+S32 -> 3 | U32: 0 | W32: 87 | X32: 35.7 | Y32: 59 | Z32: =(W32/12)*(X32/12) -> 21.56875 | AA32: =(W32/12)*(X32/12)*(Y32/12) -> 106.04635 | AB32: 3992 | AC32: 43 | AD32: 5 | AE32: 0 | AF32: 0 | AG32: 0 | AH32: 0 | AI32: 0 | AJ32: 0 | AK32: 0 | AL32: 0 | AM32: 0 | AO32: 0 | AP32: 0 | AQ32: 0 | AR32: 0 | AS32: 0 | AT32: 0 | AV32: =1809/Z32 -> 83.871342 | AW32: =120000/AB32 -> 30.06012 | AX32: =AB32/120000 -> 0.033266667 | AZ32: =1850/Z32 -> 85.77224 | BA32: =412000/AB32 -> 103.20641 | BB32: =Z32/1850 -> 0.011658784
A33: B1045 | B33: GENERATOR 100KW MEP 807 | C33: UT | D33: 0 | E33: 0 | F33: 0 | G33: 0 | H33: 0 | I33: 0 | J33: 0 | K33: 0 | L33: 0 | M33: 2 | N33: 0 | O33: 0 | P33: 0 | Q33: 0 | R33: 1 | S33: 1 | T33: =R33+S33 -> 2 | U33: 0 | W33: 106 | X33: 40 | Y33: 65 | Z33: =(W33/12)*(X33/12) -> 29.444444 | AA33: =(W33/12)*(X33/12)*(Y33/12) -> 159.49074 | AB33: 6100 | AC33: 66 | AD33: 8 | AE33: 0 | AF33: 0 | AG33: 0 | AH33: 0 | AI33: 0 | AJ33: 0 | AK33: 0 | AL33: 0 | AM33: 0 | AO33: 0 | AP33: 0 | AQ33: 0 | AR33: 0 | AS33: 0 | AT33: 0 | AV33: =1809/Z33 -> 61.437736 | AW33: =120000/AB33 -> 19.672131 | AX33: =AB33/120000 -> 0.050833333 | AZ33: =1850/Z33 -> 62.830189 | BA33: =412000/AB33 -> 67.540984 | BB33: =Z33/1850 -> 0.015915916
A34: B1298 | B34: LAUNCHER,MINE CLEAR MK155 (MTVR/AAV TOW) | C34: MOBILITY | D34: 0 | E34: 0 | F34: 15 | G34: 38 | H34: 0 | I34: 0 | J34: 0 | K34: 0 | L34: 0 | M34: 0 | N34: 0 | O34: 0 | P34: 0 | Q34: 0 | R34: 15 | S34: 15 | T34: =R34+S34 -> 30 | U34: 0 | W34: 187 | X34: 95 | Y34: 74 | Z34: 761 | AA34: =(W34/12)*(X34/12)*(Y34/12) -> 760.76968 | AB34: 6800 | AC34: 0 | AD34: 0 | AE34: 0 | AF34: 0 | AG34: 0 | AH34: 0 | AI34: 0 | AJ34: 0 | AK34: 0 | AL34: 0 | AM34: 0 | AO34: 0 | AP34: 0 | AQ34: 0 | AR34: 0 | AS34: 0 | AT34: 0 | AV34: =1809/Z34 -> 2.3771353 | AW34: =120000/AB34 -> 17.647059 | AX34: =Z34/1809 -> 0.42067441 | AZ34: =1850/Z34 -> 2.4310118 | BA34: =412000/AB34 -> 60.588235 | BB34: =Z34/1850 -> 0.41135135
A35: B1315 | B35: LAUNCHER,MINE CLEAR MK154 (AAV MOUNT) | C35: MOBILITY | D35: 12 | E35: 0 | F35: 3 | G35: 0 | H35: 0 | I35: 0 | J35: 0 | K35: 0 | L35: 0 | M35: 0 | N35: 0 | O35: 0 | P35: 0 | Q35: 0 | R35: 6 | S35: 6 | T35: =R35+S35 -> 12 | U35: 0 | W35: 175.8 | X35: 95.9 | Y35: 60.5 | Z35: =(W35/12)*(X35/12) -> 117.07792 | AA35: =(W35/12)*(X35/12)*(Y35/12) -> 590.26783 | AB35: 8790 | AC35: 0 | AD35: 0 | AE35: 0 | AF35: 0 | AG35: 0 | AH35: 0 | AI35: 0 | AJ35: 0 | AK35: 0 | AL35: 0 | AM35: 0 | AO35: 0 | AP35: 0 | AQ35: 0 | AR35: 0 | AS35: 0 | AT35: 0 | AV35: =1809/Z35 -> 15.451249 | AW35: =120000/AB35 -> 13.651877 | AX35: =AB35/120000 -> 0.07325 | AZ35: =1850/Z35 -> 15.801443 | BA35: =412000/AB35 -> 46.871445 | BB35: =Z35/1850 -> 0.06328536
A36: B2085 | B36: FUEL SIXCON | C36: FUEL | D36: 18 | E36: 3 | F36: 14 | G36: 12 | H36: 8 | I36: 0 | J36: 20 | K36: 0 | L36: 29 | M36: 8 | N36: 2 | O36: 2 | P36: 2 | Q36: 10 | R36: 32 | S36: 32 | T36: =R36+S36 -> 64 | U36: 0 | W36: 96 | X36: 77.5 | Y36: 47.4 | Z36: =(W36/12)*(X36/12) -> 51.666667 | AA36: =(W36/12)*(X36/12)*(Y36/12) -> 204.08333 | AB36: 8895 | AC36: 850 | AD36: 0 | AE36: 0 | AF36: 0 | AG36: 0 | AH36: 0 | AI36: 0 | AJ36: 0 | AK36: 0 | AL36: 0 | AM36: 0 | AO36: 0 | AP36: 0 | AQ36: 0 | AR36: 0 | AS36: 0 | AT36: 0 | AV36: =1809/Z36 -> 35.012903 | AW36: =120000/AB36 -> 13.490725 | AX36: =AB36/120000 -> 0.074125 | AZ36: =1850/Z36 -> 35.806452 | BA36: =412000/AB36 -> 46.318156 | BB36: =Z36/1850 -> 0.027927928
A37: B2086 | B37: WATER SIXCON | C37: WATER | D37: 2 | E37: 0 | F37: 6 | G37: 4 | H37: 2 | I37: 0 | J37: 4 | K37: 0 | L37: 14 | M37: 0 | N37: 0 | O37: 0 | P37: 0 | Q37: 0 | R37: 24 | S37: 24 | T37: =R37+S37 -> 48 | U37: 0 | W37: 96 | X37: 77.5 | Y37: 47.4 | Z37: =(W37/12)*(X37/12) -> 51.666667 | AA37: =(W37/12)*(X37/12)*(Y37/12) -> 204.08333 | AB37: 10000 | AC37: 0 | AD37: 0 | AE37: 0 | AF37: 0 | AG37: 0 | AH37: 900 | AI37: 7506 | AJ37: 0 | AK37: 0 | AL37: 0 | AM37: 0 | AO37: 0 | AP37: 0 | AQ37: 0 | AR37: 0 | AS37: 0 | AT37: 0 | AV37: =1809/Z37 -> 35.012903 | AW37: =120000/AB37 -> 12 | AX37: =AB37/120000 -> 0.083333333 | AZ37: =1850/Z37 -> 35.806452 | BA37: =412000/AB37 -> 41.2 | BB37: =Z37/1850 -> 0.027927928
A38: B2130 | B38: 3K GAL WATER BLADDER | C38: WATER | D38: 0 | E38: 0 | F38: 4 | G38: 0 | H38: 0 | I38: 0 | J38: 0 | K38: 0 | L38: 0 | M38: 0 | N38: 0 | O38: 0 | P38: 0 | Q38: 0 | R38: 0 | S38: 0 | T38: =R38+S38 -> 0 | U38: 0 | W38: 156 | X38: 156 | Y38: 65 | Z38: =(W38/12)*(X38/12) -> 169 | AA38: =(W38/12)*(X38/12)*(Y38/12) -> 915.41667 | AB38: 0 | AC38: 0 | AD38: 0 | AE38: 0 | AF38: 0 | AG38: 0 | AH38: 3000 | AI38: 25020 | AJ38: 0 | AK38: 0 | AL38: 0 | AM38: 0 | AO38: 0 | AP38: 0 | AQ38: 0 | AR38: 0 | AS38: 0 | AT38: 0 | AV38: 0 | AW38: 0 | AX38: 0 | AZ38: 0 | BA38: 0 | BB38: 0
A39: B2460 | B39: TRACTOR, FULL TRACKED | C39: HE | D39: 0 | E39: 0 | F39: 0 | G39: 0 | H39: 0 | I39: 0 | J39: 0 | K39: 0 | L39: 0 | M39: 0 | N39: 0 | O39: 0 | P39: 0 | Q39: 3 | R39: 5 | S39: 5 | T39: =R39+S39 -> 10 | U39: 0 | W39: 191 | X39: 110 | Y39: 116 | Z39: =(W39/12)*(X39/12) -> 145.90278 | AA39: =(W39/12)*(X39/12)*(Y39/12) -> 1410.3935 | AB39: 25100 | AC39: 56 | AD39: 7 | AE39: 1 | AF39: 0 | AG39: 0 | AH39: 0 | AI39: 0 | AJ39: 0 | AK39: 0 | AL39: 0 | AM39: 0 | AO39: 0 | AP39: 0 | AQ39: 0 | AR39: 0 | AS39: 0 | AT39: 0 | AV39: =1809/Z39 -> 12.398667 | AW39: =120000/AB39 -> 4.7808765 | AX39: =AB39/120000 -> 0.20916667 | AZ39: =1850/Z39 -> 12.679676 | BA39: =412000/AB39 -> 16.414343 | BB39: =Z39/1850 -> 0.078866366
A40: B2483 | B40: LOADER,BACKHOE (BHL) | C40: HE | D40: 0 | E40: 0 | F40: 5 | G40: 12 | H40: 0 | I40: 0 | J40: 0 | K40: 0 | L40: 0 | M40: 0 | N40: 0 | O40: 0 | P40: 0 | Q40: 0 | R40: 3 | S40: 3 | T40: =R40+S40 -> 6 | U40: 0 | W40: 276 | X40: 93 | Y40: 142 | Z40: =(W40/12)*(X40/12) -> 178.25 | AA40: =(W40/12)*(X40/12)*(Y40/12) -> 2109.2917 | AB40: 21605 | AC40: 36 | AD40: 6 | AE40: 1 | AF40: 0 | AG40: 0 | AH40: 0 | AI40: 0 | AJ40: 0 | AK40: 0 | AL40: 0 | AM40: 0 | AO40: 0 | AP40: 0 | AQ40: 0 | AR40: 0 | AS40: 0 | AT40: 0 | AV40: =1809/Z40 -> 10.148668 | AW40: =120000/AB40 -> 5.5542698 | AX40: =AB40/120000 -> 0.18004167 | AZ40: =1850/Z40 -> 10.378682 | BA40: =412000/AB40 -> 19.06966 | BB40: =Z40/1850 -> 0.096351351
...

Sheet MANPOWER (UNCLASS)
A1: 3D DIV HQ | B1: 90 | C1: 252 | D1: 10 | E1: 36 | F1: =B1+C1+D1+E1 -> 388 | G1: 3D MAR | H1: =H2+H3+H4+H10+H16 -> 170 | I1: =I2+I3+I4+I10+I16 -> 2878 | J1: =J2+J3+J4+J10+J16 -> 14 | K1: =K2+K3+K4+K10+K16 -> 225 | L1: =H1+I1+J1+K1 -> 3287 | O1: 1ST CEB | P1: =SUM(P2:P7) -> 41 | Q1: =SUM(Q2:Q7) -> 859 | R1: =SUM(R2:R7) -> 2 | S1: =SUM(S2:S7) -> 26 | T1: =SUM(P1:S1) -> 928 | U1: 3D LAR BN | V1: =SUM(V2:V6) -> 44 | W1: =SUM(W2:W6) -> 837 | X1: =SUM(X2:X6) -> 3 | Y1: =SUM(Y2:Y6) -> 77 | Z1: =SUM(V1:Y1) -> 961
A2: HQBN | B2: =B3+B4+B5+B6+B7+B8+B9 -> 36 | C2: =C3+C4+C5+C6+C7+C8+C9 -> 572 | D2: =D3+D4+D5+D6+D7+D8+D9 -> 3 | E2: =E3+E4+E5+E6+E7+E8+E9 -> 24 | F2: =B2+C2+D2+E2 -> 635 | G2: HQ CO | H2: 31 | I2: 217 | J2: 5 | K2: 25 | L2: =H2+I2+J2+K2 -> 278 | O2: SUPPORT CO | P2: 6 | Q2: 220 | R2: 0 | S2: 0 | T2: =SUM(P2:S2) -> 226 | U2: CO A | V2: 5 | W2: 133 | X2: 0 | Y2: 0 | Z2: =SUM(V2:Y2) -> 138
A3: COMM CO | B3: 15 | C3: 295 | D3: 0 | E3: 0 | F3: =B3+C3+D3+E3 -> 310 | G3: CAC | H3: 4 | I3: 114 | J3: 0 | K3: 2 | L3: =H3+I3+J3+K3 -> 120 | O3: ASSAULT CO | P3: 5 | Q3: 206 | R3: 0 | S3: 0 | T3: =SUM(P3:S3) -> 211 | U3: CO B | V3: 5 | W3: 133 | X3: 0 | Y3: 0 | Z3: =SUM(V3:Y3) -> 138
A4: TRUCK CO | B4: 8 | C4: 129 | D4: 0 | E4: 0 | F4: =B4+C4+D4+E4 -> 137 | G4: V13 | H4: =H5+H6+H7+H8+H9 -> 45 | I4: =I5+I6+I7+I8+I9 -> 849 | J4: =J5+J6+J7+J8+J9 -> 3 | K4: =K5+K6+K7+K8+K9 -> 66 | L4: =H4+I4+J4+K4 -> 963 | O4: CBT ENGR CO 1 | P4: 5 | Q4: 109 | R4: 0 | S4: 0 | T4: =SUM(P4:S4) -> 114 | U4: CO C | V4: 5 | W4: 133 | X4: 0 | Y4: 0 | Z4: =SUM(V4:Y4) -> 138
A5: HQ CO | B5: 9 | C5: 104 | D5: 3 | E5: 24 | F5: =B5+C5+D5+E5 -> 140 | G5: H&S CO | H5: 22 | I5: 180 | J5: 3 | K5: 66 | L5: =H5+I5+J5+K5 -> 271 | O5: CBT ENGR CO 2 | P5: 5 | Q5: 109 | R5: 0 | S5: 0 | T5: =SUM(P5:S5) -> 114 | U5: CO D | V5: 5 | W5: 133 | X5: 0 | Y5: 0 | Z5: =SUM(V5:Y5) -> 138
A6: DS TM 1 | B6: 1 | C6: 7 | D6: 0 | E6: 0 | F6: =B6+C6+D6+E6 -> 8 | G6: LINE CO 1 | H6: 6 | I6: 176 | J6: 0 | K6: 0 | L6: =H6+I6+J6+K6 -> 182 | O6: CBT ENGR CO 3 | P6: 5 | Q6: 109 | R6: 0 | S6: 0 | T6: =SUM(P6:S6) -> 114 | U6: H&S CO | V6: 24 | W6: 305 | X6: 3 | Y6: 77 | Z6: =SUM(V6:Y6) -> 409
A7: JWTC | B7: 2 | C7: 15 | D7: 0 | E7: 0 | F7: =B7+C7+D7+E7 -> 17 | G7: LINE CO 2 | H7: 6 | I7: 176 | J7: 0 | K7: 0 | L7: =H7+I7+J7+K7 -> 182 | O7: H&S CO | P7: 15 | Q7: 106 | R7: 2 | S7: 26 | T7: =SUM(P7:S7) -> 149 | U7: LE BN | V7: =SUM(V8:V11) -> 25 | W7: =SUM(W8:W11) -> 501 | X7: =SUM(X8:X11) -> 1 | Y7: =SUM(Y8:Y11) -> 17 | Z7: =SUM(V7:Y7) -> 544
A8: DS TM 2 | B8: 1 | C8: 7 | D8: 0 | E8: 0 | F8: =B8+C8+D8+E8 -> 8 | G8: LINE CO 3 | H8: 6 | I8: 176 | J8: 0 | K8: 0 | L8: =H8+I8+J8+K8 -> 182 | O8: 1ST TANKS | P8: =SUM(P9:P13) -> 48 | Q8: =SUM(Q9:Q13) -> 735 | R8: =SUM(R9:R13) -> 2 | S8: =SUM(S9:S13) -> 31 | T8: =SUM(P8:S8) -> 816 | U8: H&S CO | V8: 10 | W8: 132 | X8: 1 | Y8: 17 | Z8: =SUM(V8:Y8) -> 160
A9: SEC COMM | B9: 0 | C9: 15 | D9: 0 | E9: 0 | F9: =B9+C9+D9+E9 -> 15 | G9: WPNS CO | H9: 5 | I9: 141 | J9: 0 | K9: 0 | L9: =H9+I9+J9+K9 -> 146 | O9: CO A | P9: 5 | Q9: 81 | R9: 0 | S9: 0 | T9: =SUM(P9:S9) -> 86 | U9: MP CO A | V9: 5 | W9: 123 | X9: 0 | Y9: 0 | Z9: =SUM(V9:Y9) -> 128
A10: 3D RECON | B10: =B11+B12+B13+B14+B15 -> 31 | C10: =C11+C12+C13+C14+C15 -> 360 | D10: =D11+D12+D13+D14+D15 -> 2 | E10: =E11+E12+E13+E14+E15 -> 18 | F10: =B10+C10+D10+E10 -> 411 | G10: V23 | H10: =H11+H12+H13+H14+H15 -> 45 | I10: =I11+I12+I13+I14+I15 -> 849 | J10: =J11+J12+J13+J14+J15 -> 3 | K10: =K11+K12+K13+K14+K15 -> 66 | L10: =H10+I10+J10+K10 -> 963 | O10: CO B | P10: 5 | Q10: 81 | R10: 0 | S10: 0 | T10: =SUM(P10:S10) -> 86 | U10: MP CO B | V10: 5 | W10: 123 | X10: 0 | Y10: 0 | Z10: =SUM(V10:Y10) -> 128
A11: CO A | B11: 3 | C11: 46 | D11: 0 | E11: 2 | F11: =B11+C11+D11+E11 -> 51 | G11: H&S CO | H11: 22 | I11: 180 | J11: 3 | K11: 66 | L11: =H11+I11+J11+K11 -> 271 | O11: CO C | P11: 5 | Q11: 81 | R11: 0 | S11: 0 | T11: =SUM(P11:S11) -> 86 | U11: MP CO C | V11: 5 | W11: 123 | X11: 0 | Y11: 0 | Z11: =SUM(V11:Y11) -> 128
A12: CO B | B12: 3 | C12: 46 | D12: 0 | E12: 2 | F12: =B12+C12+D12+E12 -> 51 | G12: LINE CO 1 | H12: 6 | I12: 176 | J12: 0 | K12: 0 | L12: =H12+I12+J12+K12 -> 182 | O12: CO D | P12: 5 | Q12: 81 | R12: 0 | S12: 0 | T12: =SUM(P12:S12) -> 86 | U12: BLT ENABLERS | V12: =SUM(V13:V15) -> 8 | W12: =SUM(W13:W15) -> 206 | X12: =SUM(X13:X15) -> 0 | Y12: =SUM(Y13:Y15) -> 3 | Z12: =SUM(V12:Y12) -> 217
A13: CO C | B13: 3 | C13: 46 | D13: 0 | E13: 2 | F13: =B13+C13+D13+E13 -> 51 | G13: LINE CO 2 | H13: 6 | I13: 176 | J13: 0 | K13: 0 | L13: =H13+I13+J13+K13 -> 182 | O13: H&S CO | P13: 28 | Q13: 411 | R13: 2 | S13: 31 | T13: =SUM(P13:S13) -> 472 | U13: AAV PLT | V13: 1 | W13: 42 | X13: 0 | Y13: 0 | Z13: 43
A14: H&S CO | B14: 12 | C14: 113 | D14: 2 | E14: 11 | F14: =B14+C14+D14+E14 -> 138 | G14: LINE CO 3 | H14: 6 | I14: 176 | J14: 0 | K14: 0 | L14: =H14+I14+J14+K14 -> 182 | O14: 3D AAV BN | P14: =SUM(P15:P19) -> 49 | Q14: =SUM(Q15:Q19) -> 1128 | R14: =SUM(R15:R19) -> 2 | S14: =SUM(S15:S19) -> 24 | T14: =SUM(P14:S14) -> 1203 | U14: ENG PLT | V14: 1 | W14: 35 | X14: 0 | Y14: 0 | Z14: 36
A15: FORCE | B15: 10 | C15: 109 | D15: 0 | E15: 1 | F15: =B15+C15+D15+E15 -> 120 | G15: WPNS CO | H15: 5 | I15: 141 | J15: 0 | K15: 0 | L15: =H15+I15+J15+K15 -> 146 | O15: CO A | P15: 6 | Q15: 185 | R15: 0 | S15: 0 | T15: =SUM(P15:S15) -> 191 | U15: BTRY | V15: 6 | W15: 129 | X15: 0 | Y15: 3 | Z15: 138
A16: CAB | B16: =B17+B18 -> 33 | C16: =C17+C18 -> 497 | D16: =D17+D18 -> 3 | E16: =E17+E18 -> 26 | F16: =B16+C16+D16+E16 -> 559 | G16: V33 | H16: =H17+H18+H19+H20+H21 -> 45 | I16: =I17+I18+I19+I20+I21 -> 849 | J16: =J17+J18+J19+J20+J21 -> 3 | K16: =K17+K18+K19+K20+K21 -> 66 | L16: =H16+I16+J16+K16 -> 963 | O16: CO B | P16: 6 | Q16: 185 | R16: 0 | S16: 0 | T16: =SUM(P16:S16) -> 191
A17: ENG CO | B17: 10 | C17: 280 | D17: 0 | E17: 0 | F17: =B17+C17+D17+E17 -> 290 | G17: H&S CO | H17: 22 | I17: 180 | J17: 3 | K17: 66 | L17: =H17+I17+J17+K17 -> 271 | O17: CO C | P17: 7 | Q17: 222 | R17: 0 | S17: 0 | T17: =SUM(P17:S17) -> 229 | U17: OTHER
A18: H&S CO | B18: 23 | C18: 217 | D18: 3 | E18: 26 | F18: =B18+C18+D18+E18 -> 269 | G18: LINE CO 1 | H18: 6 | I18: 176 | J18: 0 | K18: 0 | L18: =H18+I18+J18+K18 -> 182 | O18: CO D | P18: 8 | Q18: 207 | R18: 0 | S18: 4 | T18: =SUM(P18:S18) -> 219 | U18: HIMARS (5/11) | V18: 9 | W18: 136 | X18: 0 | Y18: 3 | Z18: =SUM(V18:Y18) -> 148
A19: 12TH MAR | B19: =B20+B21+B27 -> 105 | C19: =C20+C21+C27 -> 1201 | D19: =D20+D21+D27 -> 13 | E19: =E20+E21+E27 -> 27 | F19: =B19+C19+D19+E19 -> 1346 | G19: LINE CO 2 | H19: 6 | I19: 176 | J19: 0 | K19: 0 | L19: =H19+I19+J19+K19 -> 182 | O19: H&S CO | P19: 22 | Q19: 329 | R19: 2 | S19: 20 | T19: =SUM(P19:S19) -> 373 | U19: FIST (3/11) | V19: 16 | W19: 0 | X19: 76 | Z19: =SUM(V19:Y19) -> 92
A20: REGT HQ BTRY | B20: 27 | C20: 346 | D20: 3 | E20: 7 | F20: =B20+C20+D20+E20 -> 383 | G20: LINE CO 3 | H20: 6 | I20: 176 | J20: 0 | K20: 0 | L20: =H20+I20+J20+K20 -> 182 | O20: CLB 3 | P20: =SUM(P21:P23) -> 35 | Q20: =SUM(Q21:Q23) -> 529 | R20: =SUM(R21:R23) -> 2 | S20: =SUM(S21:S23) -> 19 | T20: =SUM(P20:S20) -> 585 | U20: AAOE | V20: 15 | W20: 155 | X20: 0 | Y20: 2 | Z20: =SUM(V20:Y20) -> 172
A21: 1ST BN, 12TH MAR | B21: =B22+B23+B24+B25+B26 -> 51 | C21: =C22+C23+C24+C25+C26 -> 585 | D21: =D22+D23+D24+D25+D26 -> 5 | E21: =E22+E23+E24+E25+E26 -> 13 | F21: =B21+C21+D21+E21 -> 654 | G21: WPNS CO | H21: 5 | I21: 141 | J21: 0 | K21: 0 | L21: =H21+I21+J21+K21 -> 146 | O21: TRANS SVC | P21: 6 | Q21: 208 | R21: 0 | S21: 0 | T21: =SUM(P21:S21) -> 214 | U21: OPP | V21: 1 | W21: 58 | X21: 0 | Y21: 1 | Z21: =SUM(V21:Y21) -> 60
A22: HQ BTRY | B22: 21 | C22: 141 | D22: 5 | E22: 4 | F22: =B22+C22+D22+E22 -> 171 | G22: 4TH MAR | H22: =H23 -> 28 | I22: =I23 -> 203 | J22: =J23 -> 4 | K22: =K23 -> 6 | L22: =H22+I22+J22+K22 -> 241 | O22: SPT CO | P22: 13 | Q22: 131 | R22: 0 | S22: 8 | T22: =SUM(P22:S22) -> 152 | U22: CAG | Z22: 156
A23: BTRY A | B23: 6 | C23: 129 | D23: 0 | E23: 3 | F23: =B23+C23+D23+E23 -> 138 | G23: HQ CO | H23: 28 | I23: 203 | J23: 4 | K23: 6 | L23: 241 | O23: H&S CO | P23: 16 | Q23: 190 | R23: 2 | S23: 11 | T23: =SUM(P23:S23) -> 219 | U23: CA DET | Z23: 10
A24: BTRY B | B24: 6 | C24: 129 | D24: 0 | E24: 3 | F24: =B24+C24+D24+E24 -> 138 | U24: CA TEAM | Z24: 5
A25: BTRY C | B25: 6 | C25: 129 | D25: 0 | E25: 3 | F25: =B25+C25+D25+E25 -> 138
A26: FIST | B26: 12 | C26: 57 | D26: 0 | E26: 0 | F26: =B26+C26+D26+E26 -> 69 | G26: 3D MARDIV T/O TOTAL | H26: MO | I26: ME | J26: NO | K26: NE | L26: TOT
A27: 3D BN, 12TH MAR | B27: =B28+B29 -> 27 | C27: =C28+C29 -> 270 | D27: =D28+D29 -> 5 | E27: =E28+E29 -> 7 | F27: =B27+C27+D27+E27 -> 309 | H27: =SUM(H22,H1,B1,B2,B10,B16,B19) -> 493 | I27: =SUM(I22,I1,C1,C2,C10,C16,C19) -> 5963 | J27: =SUM(J22,J1,D1,D2,D10,D16,D19) -> 49 | K27: =SUM(K22,K1,E1,E2,E10,E16,E19) -> 362 | L27: =SUM(H27:K27) -> 6867
A28: HQ BTRY | B28: 21 | C28: 141 | D28: 5 | E28: 4 | F28: =B28+C28+D28+E28 -> 171
A29: BTRY I | B29: 6 | C29: 129 | D29: 0 | E29: 3 | F29: =B29+C29+D29+E29 -> 138
H30: CALCULATIONS - 3d MARDIV TOTAL
A31: TYPICAL BREAK-OUT
A32: 3D DIV HQ | B32: 90 | C32: 252 | D32: 10 | E32: 36 | F32: 388 | N32: AE/ASHORE | P32: AFOE
A33: HQBN | B33: 36 | C33: 572 | D33: 3 | E33: 24 | F33: 635 | N33: QTY OF UNIT | O33: TOTAL | P33: QTY OF UNIT | Q33: TOTAL | R33: OVERALL
A34: 3D MAR | B34: 170 | C34: 2878 | D34: 14 | E34: 225 | F34: 3287 | H34: DIV HQ | I34: 90 | J34: 252 | K34: 10 | L34: 36 | M34: 388 | N34: 0 | O34: =M34*N34 -> 0 | P34: 0 | Q34: =M34*P34 -> 0 | R34: =O34+Q34 -> 0
A35: 4TH MAR | B35: 170 | C35: 2878 | D35: 14 | E35: 225 | F35: 3287 | H35: DIV HQBN | I35: 36 | J35: 572 | K35: 3 | L35: 24 | M35: 635 | N35: 0 | O35: =M35*N35 -> 0 | P35: 0 | Q35: =M35*P35 -> 0 | R35: =O35+Q35 -> 0
A36: 7TH MAR | B36: 170 | C36: 2878 | D36: 14 | E36: 225 | F36: 3287 | H36: INF REGT | I36: 170 | J36: 2878 | K36: 14 | L36: 225 | M36: 3287 | N36: 0 | O36: =M36*N36 -> 0 | P36: 0 | Q36: =M36*P36 -> 0 | R36: =O36+Q36 -> 0
A37: 3D RECON | B37: 31 | C37: 360 | D37: 2 | E37: 18 | F37: 411 | H37: IN REGT HQ CO | I37: 31 | J37: 217 | K37: 5 | L37: 25 | M37: =I37+J37+K37+L37 -> 278 | N37: 0 | O37: =M37*N37 -> 0 | P37: 0 | Q37: =M37*P37 -> 0 | R37: =O37+Q37 -> 0
A38: CAB | B38: 33 | C38: 497 | D38: 3 | E38: 26 | F38: 559 | H38: INF BN | I38: 45 | J38: 849 | K38: 3 | L38: 66 | M38: 963 | N38: 0 | O38: =M38*N38 -> 0 | P38: 0 | Q38: =M38*P38 -> 0 | R38: =O38+Q38 -> 0
A39: 12TH MAR | B39: 105 | C39: 1201 | D39: 13 | E39: 27 | F39: 1346 | H39: ARTY REGT HQ | I39: 27 | J39: 346 | K39: 3 | L39: 7 | M39: =I39+J39+K39+L39 -> 383 | N39: 0 | O39: =M39*N39 -> 0 | P39: 0 | Q39: =M39*P39 -> 0 | R39: =O39+Q39 -> 0
A40: 1ST BN, 12TH MAR | B40: 51 | C40: 585 | D40: 5 | E40: 13 | F40: 654 | G40: 18951 | H40: ARTY BN | I40: 51 | J40: 585 | K40: 5 | L40: 13 | M40: 654 | N40: 0 | O40: =M40*N40 -> 0 | P40: 0 | Q40: =M40*P40 -> 0 | R40: =O40+Q40 -> 0
...

Sheet CL V SUM (UNCLASS)
A1: UNIT TYPE | B1: COMBAT LD (PALLETS) | C1: CL LBS | D1: CL ST | E1: ASLT RATE (PALLETS) | F1: ASLT LBS | G1: ASLT ST | H1: SUST RATE (PALLETS) | I1: SUST LBS | J1: SUST ST
A2: DIV HQ | B2: 21.29 | C2: 40445.2 | D2: =C2/2000 -> 20.2226 | E2: 1.5 | F2: 2910.41 | G2: =F2/2000 -> 1.455205 | H2: 0.53 | I2: 447.45 | J2: =I2/2000 -> 0.223725
